Workbook

Sheet 选手工资
A1: 选手 | B1: 初始工资 | C1: 更新工资0507 | D1: 更新工资0508 | E1: 更新工资0509
A2: D | B2: 10 | C2: 9.5 | D2: 8.5 | E2: 7.5
A3: ldxy | B3: 8 | C3: 7.5 | D3: 6.5 | E3: 5.5
A4: 马忠 | B4: 8 | C4: 8.5 | D4: 8 | E4: 8
A5: 郝哥 | B5: 7.5 | C5: 7.5 | D5: 8.5 | E5: 9.5
A6: 关羽 | B6: 7.5 | C6: 8 | D6: 8.5 | E6: 8.5
A7: cac | B7: 7.5 | C7: 7.5 | D7: 7.5 | E7: 6.5
A8: xian | B8: 7.5 | C8: 10.5 | D8: 10.5 | E8: 10.5
A9: 阵容 | B9: 7 | C9: 7 | D9: 6 | E9: 5.5
A10: zjw | B10: 7 | C10: 7 | D10: 7 | E10: 7
A11: jin | B11: 6.5 | C11: 6.5 | D11: 6 | E11: 5
A12: 小孩 | B12: 6 | C12: 5.5 | D12: 7 | E12: 8
A13: 教练 | B13: 6 | C13: 6 | D13: 5 | E13: 5
... A29: 之后 | B29: 1 | C29: 1 | D29: 3 | E29: 3
B32: 初始工资
B33: 10
B34: 8
B35: 8
B36: 7.5
B37: 7.5
B38: 7.5
B39: 7.5
B40: 7
B41: 7
B42: 6.5
B43: 6
B44: 6
... B60: 1

Sheet 260505-1
A1: 日期 | B1: 场次 | C1: 阵营 | D1: 结果 | E1: 队伍击杀 | F1: 选手 | G1: 选手工资 | H1: 英雄 | I1: 位置 | J1: 等级 | K1: K | L1: D | M1: A | N1: 参战率 | O1: 输出占比 | P1: 财产 | Q1: 正补 | R1: 反补 | S1: GPM | T1: XPM | U1: 赏金神符 | V1: 治疗 | W1: 英雄伤害 | X1: 建筑伤害 | Y1: 承伤减免前 | Z1: 伤害减免比例 | AA1: 死亡损失金钱 | AB1: 死亡时间 | AC1: 挑选顺位 | AD1: 10分钟财产 | AE1: 10分钟等级 | AF1: 辅助道具金钱 | AG1: 堆野数 | AH1: 反眼数
A2: 260505 | B2: 1 | C2: 夜魇 | D2: 胜 | E2: 47 | F2: xian | G2: 7.5 | H2: 帕克 | I2: 2 | J2: 28 | K2: 22 | L2: 3 | M2: 17 | N2: 0.83 | O2: 0.388 | P2: 36027 | Q2: 399 | R2: 15 | S2: 761 | T2: 1027 | U2: 7 | V2: 106 | W2: 104915 | X2: 11628 | Y2: 66052 | Z2: 0.508 | AA2: 1639 | AB2: 0.16041667 | AC2: 4 | AD2: 4161 | AE2: 8 | AF2: 180 | AG2: 2 | AH2: 2
A3: 260505 | B3: 1 | C3: 夜魇 | D3: 胜 | E3: 47 | F3: 老虎 | G3: 4.5 | H3: 沉默术士 | I3: 5 | J3: 23 | K3: 4 | L3: 9 | M3: 32 | N3: 0.766 | O3: 0.09 | P3: 16637 | Q3: 65 | R3: 1 | S3: 355 | T3: 603 | U3: 2 | V3: 0 | W3: 24220 | X3: 1497 | Y3: 50639 | Z3: 0.49 | AA3: 1006 | AB3: 0.24305556 | AC3: 7 | AD3: 2264 | AE3: 5 | AF3: 1100 | AG3: 0 | AH3: 9
A4: 260505 | B4: 1 | C4: 夜魇 | D4: 胜 | E4: 47 | F4: 机器猫 | G4: 4 | H4: 破晓辰星 | I4: 3 | J4: 28 | K4: 9 | L4: 7 | M4: 24 | N4: 0.702 | O4: 0.185 | P4: 25961 | Q4: 361 | R4: 0 | S4: 607 | T4: 1044 | U4: 1 | V4: 8496 | W4: 49924 | X4: 7935 | Y4: 104990 | Z4: 0.538 | AA4: 1744 | AB4: 0.22361111 | AC4: 3 | AD4: 3493 | AE4: 6 | AF4: 130 | AG4: 0 | AH4: 1
A5: 260505 | B5: 1 | C5: 夜魇 | D5: 胜 | E5: 47 | F5: 博洋 | G5: 5.5 | H5: 编织者 | I5: 1 | J5: 27 | K5: 7 | L5: 8 | M5: 13 | N5: 0.426 | O5: 0.199 | P5: 27056 | Q5: 412 | R5: 6 | S5: 597 | T5: 846 | U5: 1 | V5: 0 | W5: 53882 | X5: 3443 | Y5: 96703 | Z5: 0.499 | AA5: 2292 | AB5: 0.32152778 | AC5: 8 | AD5: 3424 | AE5: 5 | AF5: 80 | AG5: 2 | AH5: 1
A6: 260505 | B6: 1 | C6: 夜魇 | D6: 胜 | E6: 47 | F6: valar | G6: 5.5 | H6: 小小 | I6: 4 | J6: 24 | K6: 4 | L6: 5 | M6: 32 | N6: 0.766 | O6: 0.139 | P6: 14787 | Q6: 68 | R6: 3 | S6: 337 | T6: 612 | U6: 3 | V6: 0 | W6: 37470 | X6: 1924 | Y6: 61566 | Z6: 0.402 | AA6: 758 | AB6: 0.17708333 | AC6: 10 | AD6: 1615 | AE6: 5 | AF6: 1980 | AG6: 2 | AH6: 7
A7: 260505 | B7: 1 | C7: 天辉 | D7: 负 | E7: 32 | F7: ldxy | G7: 8 | H7: 虚无之灵 | I7: 2 | J7: 27 | K7: 12 | L7: 8 | M7: 12 | N7: 0.75 | O7: 0.247 | P7: 23869 | Q7: 364 | R7: 13 | S7: 572 | T7: 894 | U7: 5 | V7: 0 | W7: 47380 | X7: 645 | Y7: 108592 | Z7: 0.566 | AA7: 2102 | AB7: 0.27361111 | AC7: 6 | AD7: 3201 | AE7: 8 | AF7: 370 | AG7: 0 | AH7: 1
A8: 260505 | B8: 1 | C8: 天辉 | D8: 负 | E8: 32 | F8: D | G8: 10 | H8: 德鲁伊 | I8: 1 | J8: 24 | K8: 8 | L8: 2 | M8: 10 | N8: 0.563 | O8: 0.385 | P8: 35934 | Q8: 627 | R8: 2 | S8: 716 | T8: 658 | U8: 2 | V8: 0 | W8: 73917 | X8: 4579 | Y8: 184578 | Z8: 0.457 | AA8: 1005 | AB8: 0.12916667 | AC8: 9 | AD8: 4216 | AE8: 7 | AF8: 0 | AG8: 2 | AH8: 2
A9: 260505 | B9: 1 | C9: 天辉 | D9: 负 | E9: 32 | F9: 记者 | G9: 5.5 | H9: 全能骑士 | I9: 3 | J9: 23 | K9: 5 | L9: 11 | M9: 14 | N9: 0.594 | O9: 0.17 | P9: 17644 | Q9: 244 | R9: 20 | S9: 399 | T9: 595 | U9: 2 | V9: 4835 | W9: 32615 | X9: 994 | Y9: 101283 | Z9: 0.479 | AA9: 3165 | AB9: 0.39930556 | AC9: 5 | AD9: 3672 | AE9: 6 | AF9: 0 | AG9: 0 | AH9: 3
A10: 260505 | B10: 1 | C10: 天辉 | D10: 负 | E10: 32 | F10: 小队 | G10: 2 | H10: 电炎绝手 | I10: 5 | J10: 18 | K10: 4 | L10: 9 | M10: 16 | N10: 0.625 | O10: 0.086 | P10: 13266 | Q10: 76 | R10: 1 | S10: 308 | T10: 372 | U10: 2 | V10: 4742 | W10: 16448 | X10: 189 | Y10: 51471 | Z10: 0.434 | AA10: 1309 | AB10: 0.27291667 | AC10: 2 | AD10: 1709 | AE10: 6 | AF10: 1520 | AG10: 0 | AH10: 9
A11: 260505 | B11: 1 | C11: 天辉 | D11: 负 | E11: 32 | F11: xinq | G11: 3 | H11: 司夜刺客 | I11: 4 | J11: 21 | K11: 3 | L11: 18 | M11: 15 | N11: 0.563 | O11: 0.113 | P11: 10344 | Q11: 22 | R11: 1 | S11: 277 | T11: 472 | U11: 2 | V11: 0 | W11: 21762 | X11: 0 | Y11: 81604 | Z11: 0.495 | AA11: 1914 | AB11: 0.51319444 | AC11: 1 | AD11: 1296 | AE11: 5 | AF11: 850 | AG11: 2 | AH11: 5
A14: 比赛ID | B14: 8798951370
A15: 比赛时长 | B15: 51：45

Sheet 260505-2
A1: 日期 | B1: 场次 | C1: 阵营 | D1: 结果 | E1: 队伍击杀 | F1: 选手 | G1: 选手工资 | H1: 英雄 | I1: 位置 | J1: 等级 | K1: K | L1: D | M1: A | N1: 参战率 | O1: 输出占比 | P1: 财产 | Q1: 正补 | R1: 反补 | S1: GPM | T1: XPM | U1: 赏金神符 | V1: 治疗 | W1: 英雄伤害 | X1: 建筑伤害 | Y1: 承伤减免前 | Z1: 伤害减免比例 | AA1: 死亡损失金钱 | AB1: 死亡时间 | AC1: 挑选顺位 | AD1: 10分钟财产 | AE1: 10分钟等级 | AF1: 辅助道具金钱 | AG1: 堆野数 | AH1: 反眼数
A2: 260505 | B2: 2 | C2: 天辉 | D2: 胜 | E2: 36 | F2: 博洋 | G2: 5.5 | H2: 主宰 | I2: 1 | J2: 25 | K2: 12 | L2: 4 | M2: 11 | N2: 0.639 | O2: 0.318 | P2: 29477 | Q2: 435 | R2: 5 | S2: 744 | T2: 878 | U2: 2 | V2: 17731 | W2: 45321 | X2: 16646 | Y2: 39358 | Z2: 0.467 | AA2: 1312 | AB2: 0.15625 | AC2: 5 | AD2: 4307 | AE2: 7 | AF2: 0 | AG2: 2 | AH2: 0
A3: 260505 | B3: 2 | C3: 天辉 | D3: 胜 | E3: 36 | F3: xian | G3: 7.5 | H3: 虚无之灵 | I3: 2 | J3: 25 | K3: 16 | L3: 2 | M3: 13 | N3: 0.806 | O3: 0.309 | P3: 26879 | Q3: 325 | R3: 10 | S3: 689 | T3: 853 | U3: 6 | V3: 0 | W3: 43978 | X3: 8718 | Y3: 58323 | Z3: 0.51 | AA3: 675 | AB3: 0.084722222 | AC3: 2 | AD3: 3256 | AE3: 7 | AF3: 130 | AG3: 1 | AH3: 0
A4: 260505 | B4: 2 | C4: 天辉 | D4: 胜 | E4: 36 | F4: 记者 | G4: 4.5 | H4: 全能骑士 | I4: 3 | J4: 21 | K4: 4 | L4: 5 | M4: 10 | N4: 0.389 | O4: 0.157 | P4: 17223 | Q4: 170 | R4: 3 | S4: 436 | T4: 616 | U4: 0 | V4: 3329 | W4: 22332 | X4: 3930 | Y4: 47941 | Z4: 0.446 | AA4: 1110 | AB4: 0.15555556 | AC4: 6 | AD4: 3082 | AE4: 6 | AF4: 80 | AG4: 0 | AH4: 0
A5: 260505 | B5: 2 | C5: 天辉 | D5: 胜 | E5: 36 | F5: 老虎 | G5: 4.5 | H5: 干扰者 | I5: 5 | J5: 18 | K5: 4 | L5: 8 | M5: 21 | N5: 0.694 | O5: 0.099 | P5: 14099 | Q5: 46 | R5: 0 | S5: 354 | T5: 447 | U5: 1 | V5: 0 | W5: 14146 | X5: 140 | Y5: 25944 | Z5: 0.467 | AA5: 1521 | AB5: 0.22430556 | AC5: 1 | AD5: 2546 | AE5: 5 | AF5: 950 | AG5: 1 | AH5: 5
A6: 260505 | B6: 2 | C6: 天辉 | D6: 胜 | E6: 36 | F6: 教练 | G6: 6 | H6: 森海飞霞 | I6: 4 | J6: 20 | K6: 0 | L6: 4 | M6: 24 | N6: 0.667 | O6: 0.117 | P6: 12186 | Q6: 57 | R6: 2 | S6: 326 | T6: 530 | U6: 5 | V6: 5209 | W6: 16726 | X6: 429 | Y6: 20596 | Z6: 0.381 | AA6: 237 | AB6: 0.078472222 | AC6: 9 | AD6: 1590 | AE6: 5 | AF6: 1830 | AG6: 1 | AH6: 10
A7: 260505 | B7: 2 | C7: 夜魇 | D7: 负 | E7: 23 | F7: ldxy | G7: 8 | H7: 瘟疫法师 | I7: 2 | J7: 21 | K7: 13 | L7: 10 | M7: 3 | N7: 0.696 | O7: 0.402 | P7: 18588 | Q7: 299 | R7: 4 | S7: 551 | T7: 581 | U7: 1 | V7: 4085 | W7: 42145 | X7: 1299 | Y7: 66879 | Z7: 0.428 | AA7: 2948 | AB7: 0.37847222 | AC7: 7 | AD7: 5147 | AE7: 9 | AF7: 1000 | AG7: 4 | AH7: 4
A8: 260505 | B8: 2 | C8: 夜魇 | D8: 负 | E8: 23 | F8: D | G8: 10 | H8: 德鲁伊 | I8: 1 | J8: 23 | K8: 5 | L8: 0 | M8: 9 | N8: 0.609 | O8: 0.199 | P8: 29734 | Q8: 488 | R8: 9 | S8: 726 | T8: 744 | U8: 2 | V8: 0 | W8: 20801 | X8: 6991 | Y8: 81751 | Z8: 0.446 | AA8: 0 | AB8: 0 | AC8: 10 | AD8: 4630 | AE8: 8 | AF8: 0 | AG8: 0 | AH8: 2
A9: 260505 | B9: 2 | C9: 夜魇 | D9: 负 | E9: 23 | F9: valar | G9: 5.5 | H9: 潮汐猎人 | I9: 3 | J9: 22 | K9: 2 | L9: 8 | M9: 11 | N9: 0.565 | O9: 0.225 | P9: 17025 | Q9: 271 | R9: 2 | S9: 448 | T9: 628 | U9: 2 | V9: 0 | W9: 23539 | X9: 314 | Y9: 77516 | Z9: 0.607 | AA9: 1434 | AB9: 0.23263889 | AC9: 4 | AD9: 3685 | AE9: 6 | AF9: 0 | AG9: 4 | AH9: 3
A10: 260505 | B10: 2 | C10: 夜魇 | D10: 负 | E10: 23 | F10: 小队 | G10: 2 | H10: 沉默术士 | I10: 5 | J10: 17 | K10: 2 | L10: 6 | M10: 10 | N10: 0.522 | O10: 0.078 | P10: 9356 | Q10: 40 | R10: 4 | S10: 271 | T10: 397 | U10: 1 | V10: 0 | W10: 8183 | X10: 0 | Y10: 17560 | Z10: 0.409 | AA10: 532 | AB10: 0.15138889 | AC10: 3 | AD10: 1778 | AE10: 5 | AF10: 450 | AG10: 2 | AH10: 5
A11: 260505 | B11: 2 | C11: 夜魇 | D11: 负 | E11: 23 | F11: xinq | G11: 3 | H11: 莱恩 | I11: 4 | J11: 18 | K11: 1 | L11: 12 | M11: 8 | N11: 0.391 | O11: 0.096 | P11: 10122 | Q11: 46 | R11: 2 | S11: 299 | T11: 423 | U11: 1 | V11: 0 | W11: 10080 | X11: 141 | Y11: 30864 | Z11: 0.415 | AA11: 1092 | AB11: 0.27847222 | AC11: 8 | AD11: 1679 | AE11: 5 | AF11: 930 | AG11: 0 | AH11: 9
A14: 比赛ID | B14: 8799030762
A15: 比赛时长 | B15: 41：31

Sheet 260506-1
A1: 日期 | B1: 场次 | C1: 阵营 | D1: 结果 | E1: 队伍击杀 | F1: 选手 | G1: 选手工资 | H1: 英雄 | I1: 位置 | J1: 等级 | K1: K | L1: D | M1: A | N1: 参战率 | O1: 输出占比 | P1: 财产 | Q1: 正补 | R1: 反补 | S1: GPM | T1: XPM | U1: 赏金神符 | V1: 治疗 | W1: 前哨 | X1: 英雄伤害 | Y1: 建筑伤害 | Z1: 承伤减免前 | AA1: 伤害减免比例 | AB1: 死亡损失金钱 | AC1: 死亡时间 | AD1: 挑选顺位 | AE1: 10分钟财产 | AF1: 10分钟等级 | AG1: 辅助道具金钱 | AH1: 堆野数 | AI1: 反眼数
A2: 260506 | B2: 1 | C2: 天辉 | D2: 胜 | E2: 35 | F2: D | G2: 10 | H2: 沙王 | I2: 2 | J2: 22 | K2: 14 | L2: 4 | M2: 14 | N2: 0.8 | O2: 0.314 | P2: 22048 | Q2: 346 | R2: 0 | S2: 719 | T2: 889 | U2: 3 | V2: 0 | W2: 0 | X2: 28522 | Y2: 533 | Z2: 25513 | AA2: 0.449 | AB2: 391 | AC2: 0.071527778 | AD2: 9 | AE2: 5071 | AF2: 9 | AG2: 200 | AH2: 1 | AI2: 3
A3: 260506 | B3: 1 | C3: 天辉 | D3: 胜 | E3: 35 | F3: xian | G3: =VLOOKUP(F3,选手工资!A4:B31,2,FALSE) -> 7.5 | H3: 小小 | I3: 1 | J3: 22 | K3: 14 | L3: 1 | M3: 11 | N3: 0.714 | O3: 0.327 | P3: 21250 | Q3: 336 | R3: 10 | S3: 699 | T3: 833 | U3: 2 | V3: 0 | W3: 0 | X3: 29732 | Y3: 7271 | Z3: 34770 | AA3: 0.365 | AB3: 19 | AC3: 0.0125 | AD3: 2 | AE3: 4899 | AF3: 8 | AG3: 0 | AH3: 0 | AI3: 0
A4: 260506 | B4: 1 | C4: 天辉 | D4: 胜 | E4: 35 | F4: 记者 | G4: =VLOOKUP(F4,选手工资!A2:B29,2,FALSE) -> 4.5 | H4: 全能骑士 | I4: 3 | J4: 16 | K4: 2 | L4: 3 | M4: 15 | N4: 0.486 | O4: 0.113 | P4: 11919 | Q4: 178 | R4: 6 | S4: 380 | T4: 465 | U4: 3 | V4: 3924 | W4: 1 | X4: 10310 | Y4: 1319 | Z4: 31681 | AA4: 0.423 | AB4: 261 | AC4: 0.049305556 | AD4: 5 | AE4: 3125 | AF4: 6 | AG4: 0 | AH4: 0 | AI4: 0
A5: 260506 | B5: 1 | C5: 天辉 | D5: 胜 | E5: 35 | F5: 小队 | G5: =VLOOKUP(F5,选手工资!A1:B28,2,FALSE) -> 2 | H5: 干扰者 | I5: 5 | J5: 15 | K5: 1 | L5: 5 | M5: 21 | N5: 0.629 | O5: 0.073 | P5: 7287 | Q5: 16 | R5: 0 | S5: 258 | T5: 425 | U5: 2 | V5: 0 | W5: 0 | X5: 6642 | Y5: 16 | Z5: 14809 | AA5: 0.311 | AB5: 256 | AC5: 0.067361111 | AD5: 1 | AE5: 1785 | AF5: 5 | AG5: 400 | AH5: 7 | AI5: 3
A6: 260506 | B6: 1 | C6: 天辉 | D6: 胜 | E6: 35 | F6: 教练 | G6: =VLOOKUP(F6,选手工资!A5:B32,2,FALSE) -> 6 | H6: 莉娜 | I6: 4 | J6: 17 | K6: 4 | L6: 5 | M6: 18 | N6: 0.629 | O6: 0.173 | P6: 12144 | Q6: 81 | R6: 2 | S6: 367 | T6: 552 | U6: 0 | V6: 0 | W6: 0 | X6: 15758 | Y6: 1533 | Z6: 15420 | AA6: 0.318 | AB6: 150 | AC6: 0.079166667 | AD6: 6 | AE6: 1722 | AF6: 5 | AG6: 450 | AH6: 2 | AI6: 5
A7: 260506 | B7: 1 | C7: 夜魇 | D7: 负 | E7: 18 | F7: ldxy | G7: 8 | H7: 灰烬之灵 | I7: 2 | J7: 18 | K7: 3 | L7: 6 | M7: 11 | N7: 0.778 | O7: 0.25 | P7: 13960 | Q7: 230 | R7: 5 | S7: 486 | T7: 603 | U7: 2 | V7: 0 | W7: 0 | X7: 18815 | Y7: 287 | Z7: 32315 | AA7: 0.476 | AB7: 1327 | AC7: 0.14652778 | AD7: 10 | AE7: 4455 | AF7: 9 | AG7: 290 | AH7: 0 | AI7: 2
A8: 260506 | B8: 1 | C8: 夜魇 | D8: 负 | E8: 18 | F8: 马忠 | G8: 8 | H8: 钢背兽 | I8: 3 | J8: 17 | K8: 3 | L8: 8 | M8: 7 | N8: 0.556 | O8: 0.333 | P8: 13299 | Q8: 238 | R8: 13 | S8: 446 | T8: 531 | U8: 1 | V8: 0 | W8: 0 | X8: 25006 | Y8: 316 | Z8: 70756 | AA8: 0.57 | AB8: 676 | AC8: 0.16597222 | AD8: 3 | AE8: 3973 | AF8: 7 | AG8: 0 | AH8: 3 | AI8: 3
A9: 260506 | B9: 1 | C9: 夜魇 | D9: 负 | E9: 18 | F9: 博洋 | G9: =VLOOKUP(F9,选手工资!A10:B37,2,FALSE) -> 5.5 | H9: 冥魂大帝 | I9: 1 | J9: 16 | K9: 0 | L9: 6 | M9: 8 | N9: 0.444 | O9: 0.193 | P9: 13878 | Q9: 272 | R9: 8 | S9: 456 | T9: 457 | U9: 2 | V9: 0 | W9: 0 | X9: 14532 | Y9: 1380 | Z9: 36871 | AA9: 0.445 | AB9: 951 | AC9: 0.12361111 | AD9: 8 | AE9: 3669 | AF9: 6 | AG9: 0 | AH9: 3 | AI9: 0
A10: 260506 | B10: 1 | C10: 夜魇 | D10: 负 | E10: 18 | F10: valar | G10: =VLOOKUP(F10,选手工资!A9:B36,2,FALSE) -> 5.5 | H10: 天涯墨客 | I10: 4 | J10: 12 | K10: 6 | L10: 8 | M10: 7 | N10: 0.722 | O10: 0.113 | P10: 5589 | Q10: 19 | R10: 5 | S10: 220 | T10: 269 | U10: 1 | V10: 0 | W10: 0 | X10: 8473 | Y10: 23 | Z10: 18469 | AA10: 0.35 | AB10: 632 | AC10: 0.17847222 | AD10: 4 | AE10: 1785 | AF10: 6 | AG10: 850 | AH10: 0 | AI10: 2
A11: 260506 | B11: 1 | C11: 夜魇 | D11: 负 | E11: 18 | F11: ODST | G11: =VLOOKUP(F11,选手工资!A8:B35,2,FALSE) -> 3.5 | H11: 暗影恶魔 | I11: 5 | J11: 12 | K11: 6 | L11: 7 | M11: 3 | N11: 0.5 | O11: 0.111 | P11: 4582 | Q11: 21 | R11: 2 | S11: 214 | T11: 283 | U11: 1 | V11: 0 | W11: 0 | X11: 8330 | Y11: 0 | Z11: 16187 | AA11: 0.343 | AB11: 382 | AC11: 0.13680556 | AD11: 7 | AE11: 2249 | AF11: 5 | AG11: 1380 | AH11: 2 | AI11: 2
A14: 比赛ID | B14: 8800088420
A15: 比赛时长 | B15: 31:18

Sheet 260506-2
A1: 日期 | B1: 场次 | C1: 阵营 | D1: 结果 | E1: 队伍击杀 | F1: 选手 | G1: 选手工资 | H1: 英雄 | I1: 位置 | J1: 等级 | K1: K | L1: D | M1: A | N1: 参战率 | O1: 输出占比 | P1: 财产 | Q1: 正补 | R1: 反补 | S1: GPM | T1: XPM | U1: 赏金神符 | V1: 治疗 | W1: 前哨 | X1: 英雄伤害 | Y1: 建筑伤害 | Z1: 承伤减免前 | AA1: 伤害减免比例 | AB1: 死亡损失金钱 | AC1: 死亡时间 | AD1: 挑选顺位 | AE1: 10分钟财产 | AF1: 10分钟等级 | AG1: 辅助道具金钱 | AH1: 堆野数 | AI1: 反眼数
A2: 260506 | B2: 2 | C2: 天辉 | D2: 负 | E2: 15 | F2: xinq | G2: =VLOOKUP(F2,选手工资!A1:B28,2,FALSE) -> 3 | H2: 干扰者 | I2: 5 | J2: 11 | K2: 2 | L2: 11 | M2: 8 | N2: 0.667 | O2: 0.137 | P2: 5509 | Q2: 18 | R2: 0 | S2: 221 | T2: 246 | U2: 0 | V2: 0 | W2: 0 | X2: 11414 | Y2: 0 | Z2: 16520 | AA2: 0.286 | AB2: 502 | AC2: 0.17986111 | AD2: 1 | AE2: 1774 | AF2: 9 | AG2: 650 | AH2: 0 | AI2: 4
A3: 260506 | B3: 2 | C3: 天辉 | D3: 负 | E3: 15 | F3: D | G3: 10 | H3: 兽王 | I3: 2 | J3: 18 | K3: 5 | L3: 4 | M3: 7 | N3: 0.8 | O3: 0.325 | P3: 14135 | Q3: 259 | R3: 5 | S3: 509 | T3: 571 | U3: 1 | V3: 0 | W3: 0 | X3: 27005 | Y3: 599 | Z3: 38085 | AA3: 0.473 | AB3: 981 | AC3: 0.12638889 | AD3: 9 | AE3: 3621 | AF3: 8 | AG3: 130 | AH3: 0 | AI3: 1
A4: 260506 | B4: 2 | C4: 天辉 | D4: 负 | E4: 15 | F4: 博洋 | G4: =VLOOKUP(F4,选手工资!A2:B29,2,FALSE) -> 5.5 | H4: 钢背兽 | I4: 3 | J4: 16 | K4: 4 | L4: 8 | M4: 7 | N4: 0.733 | O4: 0.265 | P4: 12025 | Q4: 189 | R4: 5 | S4: 410 | T4: 484 | U4: 1 | V4: 0 | W4: 0 | X4: 22008 | Y4: 376 | Z4: 62335 | AA4: 0.531 | AB4: 1085 | AC4: 0.19930556 | AD4: 5 | AE4: 3832 | AF4: 6 | AG4: 50 | AH4: 0 | AI4: 2
A5: 260506 | B5: 2 | C5: 天辉 | D5: 负 | E5: 15 | F5: 马忠 | G5: 8 | H5: 幽鬼 | I5: 1 | J5: 16 | K5: 0 | L5: 7 | M5: 11 | N5: 0.733 | O5: 0.166 | P5: 11329 | Q5: 204 | R5: 7 | S5: 365 | T5: 472 | U5: 2 | V5: 0 | W5: 0 | X5: 13815 | Y5: 0 | Z5: 26365 | AA5: 0.422 | AB5: 371 | AC5: 0.13888889 | AD5: 6 | AE5: 2754 | AF5: 5 | AG5: 130 | AH5: 0 | AI5: 0
A6: 260506 | B6: 2 | C6: 天辉 | D6: 负 | E6: 15 | F6: 老虎 | G6: =VLOOKUP(F6,选手工资!A4:B31,2,FALSE) -> 4.5 | H6: 沉默术士 | I6: 4 | J6: 12 | K6: 2 | L6: 7 | M6: 8 | N6: 0.667 | O6: 0.106 | P6: 7104 | Q6: 26 | R6: 0 | S6: 232 | T6: 298 | U6: 0 | V6: 0 | W6: 0 | X6: 8779 | Y6: 0 | Z6: 15489 | AA6: 0.399 | AB6: 300 | AC6: 0.12152778 | AD6: 2 | AE6: 2211 | AF6: 4 | AG6: 200 | AH6: 10 | AI6: 0
A7: 260506 | B7: 2 | C7: 夜魇 | D7: 胜 | E7: 36 | F7: ldxy | G7: 8 | H7: 瘟疫法师 | I7: 2 | J7: 20 | K7: 6 | L7: 3 | M7: 12 | N7: 0.5 | O7: 0.279 | P7: 18404 | Q7: 287 | R7: 5 | S7: 623 | T7: 751 | U7: 1 | V7: 8383 | W7: 0 | X7: 24077 | Y7: 3147 | Z7: 43006 | AA7: 0.466 | AB7: 242 | AC7: 0.053472222 | AD7: 10 | AE7: 4224 | AF7: 9 | AG7: 50 | AH7: 0 | AI7: 1
A8: 260506 | B8: 2 | C8: 夜魇 | D8: 胜 | E8: 36 | F8: 小孩 | G8: =VLOOKUP(F8,选手工资!A8:B35,2,FALSE) -> 6 | H8: 齐天大圣 | I8: 1 | J8: 19 | K8: 12 | L8: 3 | M8: 13 | N8: 0.694 | O8: 0.22 | P8: 19706 | Q8: 234 | R8: 13 | S8: 639 | T8: 677 | U8: 2 | V8: 0 | W8: 0 | X8: 18995 | Y8: 13668 | Z8: 30931 | AA8: 0.39 | AB8: 541 | AC8: 0.083333333 | AD8: 8 | AE8: 4794 | AF8: 7 | AG8: 0 | AH8: 0 | AI8: 1
A9: 260506 | B9: 2 | C9: 夜魇 | D9: 胜 | E9: 36 | F9: xian | G9: 7.5 | H9: 虚无之灵 | I9: 3 | J9: 18 | K9: 8 | L9: 4 | M9: 19 | N9: 0.75 | O9: 0.267 | P9: 17152 | Q9: 218 | R9: 23 | S9: 563 | T9: 614 | U9: 2 | V9: 0 | W9: 0 | X9: 22971 | Y9: 2907 | Z9: 39062 | AA9: 0.44 | AB9: 436 | AC9: 0.071527778 | AD9: 4 | AE9: 4423 | AF9: 7 | AG9: 80 | AH9: 1 | AI9: 0
A10: 260506 | B10: 2 | C10: 夜魇 | D10: 胜 | E10: 36 | F10: ODST | G10: =VLOOKUP(F10,选手工资!A7:B34,2,FALSE) -> 3.5 | H10: 邪影芳灵 | I10: 4 | J10: 15 | K10: 6 | L10: 4 | M10: 18 | N10: 0.667 | O10: 0.121 | P10: 7702 | Q10: 24 | R10: 2 | S10: 301 | T10: 437 | U10: 2 | V10: 0 | W10: 0 | X10: 10439 | Y10: 316 | Z10: 14312 | AA10: 0.275 | AB10: 395 | AC10: 0.060416667 | AD10: 3 | AE10: 2681 | AF10: 6 | AG10: 550 | AH10: 2 | AI10: 3
A11: 260506 | B11: 2 | C11: 夜魇 | D11: 胜 | E11: 36 | F11: valar | G11: =VLOOKUP(F11,选手工资!A6:B33,2,FALSE) -> 5.5 | H11: 天涯墨客 | I11: 5 | J11: 15 | K11: 4 | L11: 1 | M11: 25 | N11: 0.806 | O11: 0.113 | P11: 9330 | Q11: 28 | R11: 4 | S11: 334 | T11: 442 | U11: 5 | V11: 0 | W11: 1 | X11: 9704 | Y11: 288 | Z11: 13121 | AA11: 0.321 | AB11: 0 | AC11: 0.011111111 | AD11: 7 | AE11: 2605 | AF11: 6 | AG11: 700 | AH11: 2 | AI11: 5
A14: 比赛ID | B14: 8800139309
A15: 比赛时长 | B15: 31:00

Sheet 260506-3
A1: 日期 | B1: 场次 | C1: 阵营 | D1: 结果 | E1: 队伍击杀 | F1: 选手 | G1: 选手工资 | H1: 英雄 | I1: 位置 | J1: 等级 | K1: K | L1: D | M1: A | N1: 参战率 | O1: 输出占比 | P1: 财产 | Q1: 正补 | R1: 反补 | S1: GPM | T1: XPM | U1: 赏金神符 | V1: 治疗 | W1: 前哨 | X1: 英雄伤害 | Y1: 建筑伤害 | Z1: 承伤减免前 | AA1: 伤害减免比例 | AB1: 死亡损失金钱 | AC1: 死亡时间 | AD1: 挑选顺位 | AE1: 10分钟财产 | AF1: 10分钟等级 | AG1: 辅助道具金钱 | AH1: 堆野数 | AI1: 反眼数
A2: 260506 | B2: 3 | C2: 天辉 | D2: 胜 | E2: 46 | F2: xian | G2: =VLOOKUP(F2,选手工资!A1:B28,2,FALSE) -> 7.5 | H2: 灰烬之灵 | I2: 2 | J2: 20 | K2: 12 | L2: 1 | M2: 19 | N2: 0.674 | O2: 0.346 | P2: 18470 | Q2: 185 | R2: 23 | S2: 621 | T2: 818 | U2: 3 | V2: 110 | W2: 0 | X2: 31016 | Y2: 5780 | Z2: 27111 | AA2: 0.473 | AB2: 124 | AC2: 0.024305556 | AD2: 9 | AE2: 4818 | AF2: 9 | AG2: 290 | AH2: 0 | AI2: 1
A3: 260506 | B3: 3 | C3: 天辉 | D3: 胜 | E3: 46 | F3: 博洋 | G3: =VLOOKUP(F3,选手工资!A4:B31,2,FALSE) -> 5.5 | H3: 冥魂大帝 | I3: 1 | J3: 21 | K3: 11 | L3: 2 | M3: 10 | N3: 0.457 | O3: 0.221 | P3: 20454 | Q3: 280 | R3: 9 | S3: 722 | T3: 839 | U3: 1 | V3: 0 | W3: 0 | X3: 19867 | Y3: 8147 | Z3: 24485 | AA3: 0.33 | AB3: 313 | AC3: 0.041666667 | AD3: 5 | AE3: 5013 | AF3: 7 | AG3: 0 | AH3: 0 | AI3: 1
A4: 260506 | B4: 3 | C4: 天辉 | D4: 胜 | E4: 46 | F4: 小孩 | G4: =VLOOKUP(F4,选手工资!A5:B32,2,FALSE) -> 6 | H4: 破晓辰星 | I4: 3 | J4: 21 | K4: 10 | L4: 3 | M4: 16 | N4: 0.565 | O4: 0.222 | P4: 17721 | Q4: 216 | R4: 16 | S4: 619 | T4: 848 | U4: 2 | V4: 2951 | W4: 0 | X4: 19893 | Y4: 3285 | Z4: 30562 | AA4: 0.456 | AB4: 434 | AC4: 0.072222222 | AD4: 6 | AE4: 4345 | AF4: 7 | AG4: 50 | AH4: 0 | AI4: 1
A5: 260506 | B5: 3 | C5: 天辉 | D5: 胜 | E5: 46 | F5: 马忠 | G5: =VLOOKUP(F5,选手工资!A2:B29,2,FALSE) -> 8 | H5: 莱恩 | I5: 4 | J5: 15 | K5: 7 | L5: 6 | M5: 20 | N5: 0.587 | O5: 0.11 | P5: 8101 | Q5: 5 | R5: 5 | S5: 335 | T5: 435 | U5: 4 | V5: 0 | W5: 1 | X5: 9867 | Y5: 52 | Z5: 16167 | AA5: 0.253 | AB5: 587 | AC5: 0.12708333 | AD5: 1 | AE5: 2144 | AF5: 6 | AG5: 450 | AH5: 2 | AI5: 1
A6: 260506 | B6: 3 | C6: 天辉 | D6: 胜 | E6: 46 | F6: valar | G6: =VLOOKUP(F6,选手工资!A3:B30,2,FALSE) -> 5.5 | H6: 电炎绝手 | I6: 5 | J6: 13 | K6: 5 | L6: 7 | M6: 17 | N6: 0.478 | O6: 0.101 | P6: 8539 | Q6: 30 | R6: 0 | S6: 321 | T6: 353 | U6: 0 | V6: 587 | W6: 0 | X6: 9109 | Y6: 940 | Z6: 15920 | AA6: 0.312 | AB6: 198 | AC6: 0.13263889 | AD6: 2 | AE6: 1894 | AF6: 5 | AG6: 750 | AH6: 5 | AI6: 12
A7: 260506 | B7: 3 | C7: 夜魇 | D7: 负 | E7: 19 | F7: D | G7: 10 | H7: 蝙蝠骑士 | I7: 3 | J7: 16 | K7: 2 | L7: 7 | M7: 7 | N7: 0.474 | O7: 0.251 | P7: 10153 | Q7: 220 | R7: 2 | S7: 403 | T7: 508 | U7: 0 | V7: 0 | W7: 0 | X7: 17675 | Y7: 35 | Z7: 36775 | AA7: 0.317 | AB7: 1314 | AC7: 0.19305556 | AD7: 7 | AE7: 3736 | AF7: 7 | AG7: 50 | AH7: 1 | AI7: 0
A8: 260506 | B8: 3 | C8: 夜魇 | D8: 负 | E8: 19 | F8: 机器人 | G8: =VLOOKUP(F8,选手工资!A9:B36,2,FALSE) -> 5 | H8: 幽鬼 | I8: 1 | J8: 17 | K8: 9 | L8: 8 | M8: 8 | N8: 0.895 | O8: 0.286 | P8: 13695 | Q8: 187 | R8: 9 | S8: 523 | T8: 594 | U8: 0 | V8: 0 | W8: 0 | X8: 20130 | Y8: 0 | Z8: 28084 | AA8: 0.468 | AB8: 1460 | AC8: 0.1875 | AD8: 8 | AE8: 4141 | AF8: 6 | AG8: 0 | AH8: 0 | AI8: 0
A9: 260506 | B9: 3 | C9: 夜魇 | D9: 负 | E9: 19 | F9: ldxy | G9: 8 | H9: 祈求者 | I9: 2 | J9: 13 | K9: 1 | L9: 10 | M9: 6 | N9: 0.368 | O9: 0.167 | P9: 6389 | Q9: 108 | R9: 8 | S9: 279 | T9: 372 | U9: 1 | V9: 0 | W9: 0 | X9: 11743 | Y9: 0 | Z9: 30209 | AA9: 0.35 | AB9: 1108 | AC9: 0.2125 | AD9: 10 | AE9: 2787 | AF9: 6 | AG9: 0 | AH9: 0 | AI9: 1
A10: 260506 | B10: 3 | C10: 夜魇 | D10: 负 | E10: 19 | F10: xinq | G10: =VLOOKUP(F10,选手工资!A8:B35,2,FALSE) -> 3 | H10: 干扰者 | I10: 5 | J10: 11 | K10: 5 | L10: 13 | M10: 10 | N10: 0.789 | O10: 0.13 | P10: 4700 | Q10: 18 | R10: 0 | S10: 246 | T10: 262 | U10: 1 | V10: 0 | W10: 0 | X10: 9129 | Y10: 0 | Z10: 25987 | AA10: 0.267 | AB10: 1221 | AC10: 0.25277778 | AD10: 4 | AE10: 2223 | AF10: 6 | AG10: 600 | AH10: 2 | AI10: 10
A11: 260506 | B11: 3 | C11: 夜魇 | D11: 负 | E11: 19 | F11: 教练 | G11: =VLOOKUP(F11,选手工资!A7:B34,2,FALSE) -> 6 | H11: 森海飞霞 | I11: 4 | J11: 11 | K11: 2 | L11: 9 | M11: 6 | N11: 0.421 | O11: 0.167 | P11: 4829 | Q11: 33 | R11: 6 | S11: 226 | T11: 275 | U11: 2 | V11: 0 | W11: 0 | X11: 11726 | Y11: 0 | Z11: 17636 | AA11: 0.375 | AB11: 537 | AC11: 0.14166667 | AD11: 3 | AE11: 1498 | AF11: 5 | AG11: 450 | AH11: 1 | AI11: 1
A14: 比赛ID | B14: 8800194363
A15: 比赛时长 | B15: 28:38

Sheet 260506-4
A1: 日期 | B1: 场次 | C1: 阵营 | D1: 结果 | E1: 队伍击杀 | F1: 选手 | G1: 选手工资 | H1: 英雄 | I1: 位置 | J1: 等级 | K1: K | L1: D | M1: A | N1: 参战率 | O1: 输出占比 | P1: 财产 | Q1: 正补 | R1: 反补 | S1: GPM | T1: XPM | U1: 赏金神符 | V1: 治疗 | W1: 前哨 | X1: 英雄伤害 | Y1: 建筑伤害 | Z1: 承伤减免前 | AA1: 伤害减免比例 | AB1: 死亡损失金钱 | AC1: 死亡时间 | AD1: 挑选顺位 | AE1: 10分钟财产 | AF1: 10分钟等级 | AG1: 辅助道具金钱 | AH1: 堆野数 | AI1: 反眼数
A2: 260506 | B2: 4 | C2: 天辉 | D2: 胜 | E2: 46 | F2: ldxy | G2: =VLOOKUP(F2,选手工资!A1:B28,2,FALSE) -> 8 | H2: 痛苦女王 | I2: 2 | J2: 30 | K2: 13 | L2: 6 | M2: 22 | N2: 0.761 | O2: 0.41 | P2: 37486 | Q2: 528 | R2: 5 | S2: 713 | T2: 1159 | U2: 7 | V2: 0 | W2: 1 | X2: 82237 | Y2: 5914 | Z2: 68410 | AA2: 0.497 | AB2: 1039 | AC2: 0.16111111 | AD2: 9 | AE2: 3777 | AF2: 7 | AG2: 100 | AH2: 2 | AI2: 2
A3: 260506 | B3: 4 | C3: 天辉 | D3: 胜 | E3: 46 | F3: 马忠 | G3: =VLOOKUP(F3,选手工资!A2:B29,2,FALSE) -> 8 | H3: 破晓辰星 | I3: 3 | J3: 29 | K3: 15 | L3: 5 | M3: 19 | N3: 0.739 | O3: 0.215 | P3: 35367 | Q3: 514 | R3: 16 | S3: 674 | T3: 1000 | U3: 5 | V3: 6182 | W3: 0 | X3: 43236 | Y3: 6337 | Z3: 102848 | AA3: 0.562 | AB3: 1843 | AC3: 0.22013889 | AD3: 5 | AE3: 4964 | AF3: 7 | AG3: 0 | AH3: 2 | AI3: 0
A4: 260506 | B4: 4 | C4: 天辉 | D4: 胜 | E4: 46 | F4: 机器人 | G4: =VLOOKUP(F4,选手工资!A4:B31,2,FALSE) -> 5 | H4: 虚空假面 | I4: 1 | J4: 27 | K4: 6 | L4: 10 | M4: 16 | N4: 0.478 | O4: 0.139 | P4: 29241 | Q4: 560 | R4: 11 | S4: 634 | T4: 780 | U4: 0 | V4: 0 | W4: 0 | X4: 27914 | Y4: 550 | Z4: 87989 | AA4: 0.559 | AB4: 3861 | AC4: 0.36666667 | AD4: 6 | AE4: 3902 | AF4: 6 | AG4: 50 | AH4: 0 | AI4: 3
A5: 260506 | B5: 4 | C5: 天辉 | D5: 胜 | E5: 46 | F5: valar | G5: =VLOOKUP(F5,选手工资!A3:B30,2,FALSE) -> 5.5 | H5: 天涯墨客 | I5: 4 | J5: 24 | K5: 9 | L5: 5 | M5: 23 | N5: 0.696 | O5: 0.108 | P5: 17557 | Q5: 50 | R5: 1 | S5: 339 | T5: 564 | U5: 0 | V5: 60 | W5: 1 | X5: 21655 | Y5: 140 | Z5: 40789 | AA5: 0.542 | AB5: 933 | AC5: 0.22013889 | AD5: 1 | AE5: 2936 | AF5: 6 | AG5: 1350 | AH5: 5 | AI5: 19
A6: 260506 | B6: 4 | C6: 天辉 | D6: 胜 | E6: 46 | F6: 小队 | G6: =VLOOKUP(F6,选手工资!A5:B32,2,FALSE) -> 2 | H6: 食人魔魔法师 | I6: 5 | J6: 25 | K6: 3 | L6: 10 | M6: 30 | N6: 0.717 | O6: 0.128 | P6: 21681 | Q6: 92 | R6: 1 | S6: 442 | T6: 672 | U6: 1 | V6: 156 | W6: 0 | X6: 25744 | Y6: 3045 | Z6: 82787 | AA6: 0.481 | AB6: 2209 | AC6: 0.34930556 | AD6: 2 | AE6: 1510 | AF6: 5 | AG6: 200 | AH6: 1 | AI6: 4
A7: 260506 | B7: 4 | C7: 夜魇 | D7: 负 | E7: 36 | F7: D | G7: 10 | H7: 魅惑魔女 | I7: 2 | J7: 27 | K7: 18 | L7: 9 | M7: 7 | N7: 0.694 | O7: 0.332 | P7: 28251 | Q7: 347 | R7: 7 | S7: 604 | T7: 842 | U7: 6 | V7: 4343 | W7: 0 | X7: 59963 | Y7: 3779 | Z7: 88533 | AA7: 0.42 | AB7: 2818 | AC7: 0.34236111 | AD7: 10 | AE7: 3916 | AF7: 9 | AG7: 100 | AH7: 1 | AI7: 1
A8: 260506 | B8: 4 | C8: 夜魇 | D8: 负 | E8: 36 | F8: 小孩 | G8: =VLOOKUP(F8,选手工资!A9:B36,2,FALSE) -> 6 | H8: 齐天大圣 | I8: 1 | J8: 28 | K8: 6 | L8: 6 | M8: 9 | N8: 0.417 | O8: 0.243 | P8: 37999 | Q8: 648 | R8: 19 | S8: 727 | T8: 912 | U8: 2 | V8: 0 | W8: 1 | X8: 43868 | Y8: 6931 | Z8: 60956 | AA8: 0.503 | AB8: 2020 | AC8: 0.20277778 | AD8: 8 | AE8: 3508 | AF8: 6 | AG8: 100 | AH8: 2 | AI8: 5
A9: 260506 | B9: 4 | C9: 夜魇 | D9: 负 | E9: 36 | F9: 记者 | G9: =VLOOKUP(F9,选手工资!A10:B37,2,FALSE) -> 4.5 | H9: 全能骑士 | I9: 3 | J9: 26 | K9: 5 | L9: 8 | M9: 18 | N9: 0.639 | O9: 0.18 | P9: 24310 | Q9: 330 | R9: 7 | S9: 515 | T9: 750 | U9: 4 | V9: 3000 | W9: 2 | X9: 32475 | Y9: 510 | Z9: 114407 | AA9: 0.517 | AB9: 2706 | AC9: 0.24305556 | AD9: 4 | AE9: 4126 | AF9: 6 | AG9: 0 | AH9: 1 | AI9: 2
A10: 260506 | B10: 4 | C10: 夜魇 | D10: 负 | E10: 36 | F10: xinq | G10: =VLOOKUP(F10,选手工资!A8:B35,2,FALSE) -> 3 | H10: 杰奇洛 | I10: 5 | J10: 25 | K10: 2 | L10: 12 | M10: 19 | N10: 0.583 | O10: 0.102 | P10: 12752 | Q10: 92 | R10: 0 | S10: 321 | T10: 626 | U10: 2 | V10: 0 | W10: 2 | X10: 18534 | Y10: 44 | Z10: 40457 | AA10: 0.35 | AB10: 1448 | AC10: 0.28680556 | AD10: 3 | AE10: 1770 | AF10: 6 | AG10: 900 | AH10: 2 | AI10: 6
A11: 260506 | B11: 4 | C11: 夜魇 | D11: 负 | E11: 36 | F11: 教练 | G11: =VLOOKUP(F11,选手工资!A6:B33,2,FALSE) -> 6 | H11: 邪影芳灵 | I11: 4 | J11: 25 | K11: 5 | L11: 11 | M11: 19 | N11: 0.667 | O11: 0.144 | P11: 15015 | Q11: 107 | R11: 7 | S11: 355 | T11: 640 | U11: 3 | V11: 240 | W11: 1 | X11: 26001 | Y11: 62 | Z11: 56042 | AA11: 0.329 | AB11: 1495 | AC11: 0.31180556 | AD11: 7 | AE11: 2230 | AF11: 5 | AG11: 1800 | AH11: 4 | AI11: 4
A14: 比赛ID | B14: 8800244965
A15: 比赛时长 | B15: 56:25

Sheet 260507-1
A1: 日期 | B1: 场次 | C1: 阵营 | D1: 结果 | E1: 队伍击杀 | F1: 选手 | G1: 选手工资 | H1: 英雄 | I1: 位置 | J1: 等级 | K1: K | L1: D | M1: A | N1: 参战率 | O1: 输出占比 | P1: 财产 | Q1: 正补 | R1: 反补 | S1: GPM | T1: XPM | U1: 赏金神符 | V1: 治疗 | W1: 前哨 | X1: 英雄伤害 | Y1: 建筑伤害 | Z1: 承伤减免前 | AA1: 伤害减免比例 | AB1: 死亡损失金钱 | AC1: 死亡时间 | AD1: 挑选顺位 | AE1: 10分钟财产 | AF1: 10分钟等级 | AG1: 辅助道具金钱 | AH1: 堆野数 | AI1: 反眼数
A2: 260507 | B2: 1 | C2: 天辉 | D2: 胜 | E2: 58 | F2: 马忠 | G2: =VLOOKUP(F2,选手工资!A1:B28,2,FALSE) -> 8 | H2: 小小 | I2: 1 | J2: 26 | K2: 26 | L2: 2 | M2: 20 | N2: 0.793 | O2: 0.308 | P2: 26856 | Q2: 311 | R2: 17 | S2: 774 | T2: 1091 | U2: 2 | V2: 0 | W2: 0 | X2: 41895 | Y2: 12049 | Z2: 41420 | AA2: 0.408 | AB2: 585 | AC2: 0.075 | AD2: 9 | AE2: 4763 | AF2: 8 | AG2: 0 | AH2: 0 | AI2: 0
A3: 260507 | B3: 1 | C3: 天辉 | D3: 胜 | E3: 58 | F3: 关羽 | G3: =VLOOKUP(F3,选手工资!A3:B30,2,FALSE) -> 7.5 | H3: 灰烬之灵 | I3: 2 | J3: 25 | K3: 15 | L3: 1 | M3: 36 | N3: 0.879 | O3: 0.38 | P3: 22610 | Q3: 232 | R3: 2 | S3: 636 | T3: 977 | U3: 2 | V3: 0 | W3: 1 | X3: 51623 | Y3: 1394 | Z3: 37401 | AA3: 0.538 | AB3: 417 | AC3: 0.05625 | AD3: 5 | AE3: 3626 | AF3: 7 | AG3: 0 | AH3: 0 | AI3: 1
A4: 260507 | B4: 1 | C4: 天辉 | D4: 胜 | E4: 58 | F4: jin | G4: =VLOOKUP(F4,选手工资!A4:B31,2,FALSE) -> 6.5 | H4: 司夜刺客 | I4: 4 | J4: 20 | K4: 5 | L4: 6 | M4: 31 | N4: 0.621 | O4: 0.112 | P4: 12550 | Q4: 45 | R4: 1 | S4: 388 | T4: 600 | U4: 5 | V4: 0 | W4: 0 | X4: 15265 | Y4: 178 | Z4: 31802 | AA4: 0.47 | AB4: 719 | AC4: 0.13958333 | AD4: 2 | AE4: 1906 | AF4: 5 | AG4: 360 | AH4: 0 | AI4: 10
A5: 260507 | B5: 1 | C5: 天辉 | D5: 胜 | E5: 58 | F5: 猪猪 | G5: =VLOOKUP(F5,选手工资!A2:B29,2,FALSE) -> 3 | H5: 祸乱之源 | I5: 5 | J5: 19 | K5: 8 | L5: 10 | M5: 29 | N5: 0.638 | O5: 0.085 | P5: 12128 | Q5: 20 | R5: 1 | S5: 350 | T5: 559 | U5: 4 | V5: 195 | W5: 1 | X5: 11520 | Y5: 309 | Z5: 24932 | AA5: 0.277 | AB5: 1029 | AC5: 0.22777778 | AD5: 1 | AE5: 2335 | AF5: 5 | AG5: 1000 | AH5: 2 | AI5: 4
A6: 260507 | B6: 1 | C6: 天辉 | D6: 胜 | E6: 58 | F6: 老板 | G6: =VLOOKUP(F6,选手工资!A5:B32,2,FALSE) -> 4 | H6: 撼地者 | I6: 3 | J6: 20 | K6: 4 | L6: 9 | M6: 26 | N6: 0.517 | O6: 0.116 | P6: 14109 | Q6: 127 | R6: 1 | S6: 396 | T6: 616 | U6: 1 | V6: 0 | W6: 0 | X6: 15713 | Y6: 954 | Z6: 23935 | AA6: 0.304 | AB6: 572 | AC6: 0.16319444 | AD6: 6 | AE6: 2440 | AF6: 4 | AG6: 0 | AH6: 2 | AI6: 0
A7: 260507 | B7: 1 | C7: 夜魇 | D7: 负 | E7: 28 | F7: ldxy | G7: 8 | H7: 齐天大圣 | I7: 2 | J7: 20 | K7: 10 | L7: 10 | M7: 9 | N7: 0.679 | O7: 0.324 | P7: 13466 | Q7: 163 | R7: 24 | S7: 431 | T7: 630 | U7: 0 | V7: 0 | W7: 0 | X7: 30209 | Y7: 0 | Z7: 58878 | AA7: 0.437 | AB7: 1723 | AC7: 0.3 | AD7: 10 | AE7: 4323 | AF7: 8 | AG7: 300 | AH7: 0 | AI7: 3
A8: 260507 | B8: 1 | C8: 夜魇 | D8: 负 | E8: 28 | F8: D | G8: 10 | H8: 凯 | I8: 1 | J8: 23 | K8: 10 | L8: 8 | M8: 13 | N8: 0.821 | O8: 0.325 | P8: 17796 | Q8: 265 | R8: 14 | S8: 566 | T8: 813 | U8: 0 | V8: 0 | W8: 0 | X8: 30307 | Y8: 728 | Z8: 55377 | AA8: 0.511 | AB8: 2443 | AC8: 0.30763889 | AD8: 8 | AE8: 4318 | AF8: 7 | AG8: 50 | AH8: 1 | AI8: 0
A9: 260507 | B9: 1 | C9: 夜魇 | D9: 负 | E9: 28 | F9: 机器猫 | G9: =VLOOKUP(F9,选手工资!A6:B33,2,FALSE) -> 4 | H9: 破晓辰星 | I9: 3 | J9: 17 | K9: 3 | L9: 12 | M9: 7 | N9: 0.357 | O9: 0.168 | P9: 10486 | Q9: 172 | R9: 1 | S9: 340 | T9: 444 | U9: 4 | V9: 1064 | W9: 0 | X9: 15713 | Y9: 0 | Z9: 58120 | AA9: 0.438 | AB9: 1454 | AC9: 0.33958333 | AD9: 7 | AE9: 2596 | AF9: 6 | AG9: 240 | AH9: 1 | AI9: 0
A10: 260507 | B10: 1 | C10: 夜魇 | D10: 负 | E10: 28 | F10: 小队 | G10: =VLOOKUP(F10,选手工资!A10:B37,2,FALSE) -> 2 | H10: 干扰者 | I10: 5 | J10: 13 | K10: 2 | L10: 15 | M10: 18 | N10: 0.714 | O10: 0.098 | P10: 5871 | Q10: 10 | R10: 2 | S10: 242 | T10: 280 | U10: 0 | V10: 0 | W10: 0 | X10: 9182 | Y10: 0 | Z10: 33124 | AA10: 0.384 | AB10: 1163 | AC10: 0.29236111 | AD10: 4 | AE10: 1592 | AF10: 5 | AG10: 450 | AH10: 0 | AI10: 4
A11: 260507 | B11: 1 | C11: 夜魇 | D11: 负 | E11: 28 | F11: 老虎 | G11: =VLOOKUP(F11,选手工资!A9:B36,2,FALSE) -> 4.5 | H11: 裂魂人 | I11: 4 | J11: 13 | K11: 3 | L11: 13 | M11: 12 | N11: 0.536 | O11: 0.085 | P11: 6788 | Q11: 52 | R11: 1 | S11: 248 | T11: 279 | U11: 2 | V11: 0 | W11: 0 | X11: 7953 | Y11: 0 | Z11: 37184 | AA11: 0.387 | AB11: 1440 | AC11: 0.24791667 | AD11: 3 | AE11: 2124 | AF11: 3 | AG11: 260 | AH11: 3 | AI11: 2
A14: 比赛ID | B14: 8801269989
A15: 比赛时长 | B15: 36:07

Sheet 260507-2
A1: 日期 | B1: 场次 | C1: 阵营 | D1: 结果 | E1: 队伍击杀 | F1: 选手 | G1: 选手工资 | H1: 英雄 | I1: 位置 | J1: 等级 | K1: K | L1: D | M1: A | N1: 参战率 | O1: 输出占比 | P1: 财产 | Q1: 正补 | R1: 反补 | S1: GPM | T1: XPM | U1: 赏金神符 | V1: 治疗 | W1: 前哨 | X1: 英雄伤害 | Y1: 建筑伤害 | Z1: 承伤减免前 | AA1: 伤害减免比例 | AB1: 死亡损失金钱 | AC1: 死亡时间 | AD1: 挑选顺位 | AE1: 10分钟财产 | AF1: 10分钟等级 | AG1: 辅助道具金钱 | AH1: 堆野数 | AI1: 反眼数
A2: 260507 | B2: 2 | C2: 天辉 | D2: 胜 | E2: 59 | F2: xian | G2: =VLOOKUP(F2,选手工资!A2:B29,2,FALSE) -> 7.5 | H2: 森海飞霞 | I2: 1 | J2: 29 | K2: 15 | L2: 8 | M2: 31 | N2: 0.78 | O2: 0.425 | P2: 40875 | Q2: 632 | R2: 16 | S2: 806 | T2: 1041 | U2: 4 | V2: 0 | W2: 1 | X2: 109153 | Y2: 15908 | Z2: 101302 | AA2: 0.397 | AB2: 3900 | AC2: 0.32986111 | AD2: 1 | AE2: 4835 | AF2: 8 | AG2: 0 | AH2: 0 | AI2: 2
A3: 260507 | B3: 2 | C3: 天辉 | D3: 胜 | E3: 59 | F3: D | G3: =VLOOKUP(F3,选手工资!A1:B28,2,FALSE) -> 10 | H3: 米拉娜 | I3: 2 | J3: 30 | K3: 22 | L3: 4 | M3: 24 | N3: 0.78 | O3: 0.267 | P3: 37300 | Q3: 532 | R3: 3 | S3: 739 | T3: 1104 | U3: 8 | V3: 0 | W3: 0 | X3: 68374 | Y3: 13573 | Z3: 77743 | AA3: 0.418 | AB3: 1334 | AC3: 0.10208333 | AD3: 5 | AE3: 4328 | AF3: 8 | AG3: 50 | AH3: 3 | AI3: 4
A4: 260507 | B4: 2 | C4: 天辉 | D4: 胜 | E4: 59 | F4: 关羽 | G4: =VLOOKUP(F4,选手工资!A5:B32,2,FALSE) -> 7.5 | H4: 伐木机 | I4: 3 | J4: 26 | K4: 13 | L4: 12 | M4: 31 | N4: 0.746 | O4: 0.178 | P4: 26961 | Q4: 360 | R4: 17 | S4: 555 | T4: 667 | U4: 0 | V4: 0 | W4: 1 | X4: 45630 | Y4: 2065 | Z4: 176780 | AA4: 0.624 | AB4: 3260 | AC4: 0.32361111 | AD4: 6 | AE4: 4124 | AF4: 7 | AG4: 0 | AH4: 1 | AI4: 0
A5: 260507 | B5: 2 | C5: 天辉 | D5: 胜 | E5: 59 | F5: 老虎 | G5: =VLOOKUP(F5,选手工资!A3:B30,2,FALSE) -> 4.5 | H5: 复仇之魂 | I5: 4 | J5: 25 | K5: 5 | L5: 13 | M5: 36 | N5: 0.695 | O5: 0.076 | P5: 16245 | Q5: 123 | R5: 2 | S5: 349 | T5: 586 | U5: 2 | V5: 10 | W5: 2 | X5: 19423 | Y5: 740 | Z5: 75781 | AA5: 0.505 | AB5: 2422 | AC5: 0.38958333 | AD5: 9 | AE5: 2613 | AF5: 5 | AG5: 930 | AH5: 1 | AI5: 9
A6: 260507 | B6: 2 | C6: 天辉 | D6: 胜 | E6: 59 | F6: 猪猪 | G6: =VLOOKUP(F6,选手工资!A4:B31,2,FALSE) -> 3 | H6: 树精卫士 | I6: 5 | J6: 26 | K6: 4 | L6: 12 | M6: 40 | N6: 0.746 | O6: 0.054 | P6: 15084 | Q6: 27 | R6: 0 | S6: 339 | T6: 664 | U6: 0 | V6: 14401 | W6: 1 | X6: 13950 | Y6: 117 | Z6: 57619 | AA6: 0.34 | AB6: 1212 | AC6: 0.37638889 | AD6: 2 | AE6: 1848 | AF6: 5 | AG6: 2400 | AH6: 2 | AI6: 10
A7: 260507 | B7: 2 | C7: 夜魇 | D7: 负 | E7: 49 | F7: ldxy | G7: 8 | H7: 痛苦女王 | I7: 2 | J7: 28 | K7: 13 | L7: 10 | M7: 28 | N7: 0.837 | O7: 0.406 | P7: 34602 | Q7: 512 | R7: 12 | S7: 645 | T7: 932 | U7: 5 | V7: 45 | W7: 0 | X7: 100901 | Y7: 4166 | Z7: 159862 | AA7: 0.554 | AB7: 3257 | AC7: 0.28819444 | AD7: 7 | AE7: 4344 | AF7: 8 | AG7: 130 | AH7: 0 | AI7: 0
A8: 260507 | B8: 2 | C8: 夜魇 | D8: 负 | E8: 49 | F8: 马忠 | G8: 8 | H8: 炼金术士 | I8: 1 | J8: 29 | K8: 8 | L8: 7 | M8: 27 | N8: 0.714 | O8: 0.119 | P8: 32348 | Q8: 626 | R8: 6 | S8: 859 | T8: 1025 | U8: 9 | V8: 0 | W8: 0 | X8: 29653 | Y8: 9598 | Z8: 107338 | AA8: 0.546 | AB8: 2301 | AC8: 0.21458333 | AD8: 12 | AE8: 5094 | AF8: 7 | AG8: 50 | AH8: 6 | AI8: 1
A9: 260507 | B9: 2 | C9: 夜魇 | D9: 负 | E9: 49 | F9: 小孩 | G9: =VLOOKUP(F9,选手工资!A6:B33,2,FALSE) -> 6 | H9: 破晓辰星 | I9: 4 | J9: 28 | K9: 16 | L9: 12 | M9: 21 | N9: 0.755 | O9: 0.177 | P9: 31955 | Q9: 373 | R9: 6 | S9: 576 | T9: 858 | U9: 0 | V9: 11899 | W9: 0 | X9: 44071 | Y9: 3502 | Z9: 173618 | AA9: 0.613 | AB9: 3553 | AC9: 0.29305556 | AD9: 11 | AE9: 3799 | AF9: 7 | AG9: 0 | AH9: 0 | AI9: 0
A10: 260507 | B10: 2 | C10: 夜魇 | D10: 负 | E10: 49 | F10: 教练 | G10: =VLOOKUP(F10,选手工资!A8:B35,2,FALSE) -> 6 | H10: 裂魂人 | I10: 4 | J10: 25 | K10: 4 | L10: 13 | M10: 34 | N10: 0.776 | O10: 0.061 | P10: 16898 | Q10: 100 | R10: 4 | S10: 341 | T10: 603 | U10: 2 | V10: 1671 | W10: 5 | X10: 15206 | Y10: 720 | Z10: 88678 | AA10: 0.5 | AB10: 1710 | AC10: 0.29236111 | AD10: 4 | AE10: 2224 | AF10: 5 | AG10: 2130 | AH10: 0 | AI10: 14
A11: 260507 | B11: 2 | C11: 夜魇 | D11: 负 | E11: 49 | F11: 记者 | G11: =VLOOKUP(F11,选手工资!A10:B37,2,FALSE) -> 4.5 | H11: 工程师 | I11: 5 | J11: 23 | K11: 7 | L11: 17 | M11: 30 | N11: 0.755 | O11: 0.236 | P11: 16744 | Q11: 127 | R11: 2 | S11: 360 | T11: 500 | U11: 1 | V11: 5406 | W11: 0 | X11: 58651 | Y11: 1033 | Z11: 47431 | AA11: 0.475 | AB11: 2405 | AC11: 0.40486111 | AD11: 8 | AE11: 2193 | AF11: 5 | AG11: 1030 | AH11: 8 | AI11: 12
A14: 比赛ID | B14: 8801336033
A15: 比赛时长 | B15: 59:13

Sheet 260507-3
A1: 日期 | B1: 场次 | C1: 阵营 | D1: 结果 | E1: 队伍击杀 | F1: 选手 | G1: 选手工资 | H1: 英雄 | I1: 位置 | J1: 等级 | K1: K | L1: D | M1: A | N1: 参战率 | O1: 输出占比 | P1: 财产 | Q1: 正补 | R1: 反补 | S1: GPM | T1: XPM | U1: 赏金神符 | V1: 治疗 | W1: 前哨 | X1: 英雄伤害 | Y1: 建筑伤害 | Z1: 承伤减免前 | AA1: 伤害减免比例 | AB1: 死亡损失金钱 | AC1: 死亡时间 | AD1: 挑选顺位 | AE1: 10分钟财产 | AF1: 10分钟等级 | AG1: 辅助道具金钱 | AH1: 堆野数 | AI1: 反眼数
A2: 260507 | B2: 3 | C2: 天辉 | D2: 负 | E2: 12 | F2: D | G2: =VLOOKUP(F2,选手工资!A2:B29,2,FALSE) -> 10 | H2: 朗戈 | I2: 3 | J2: 15 | K2: 2 | L2: 7 | M2: 8 | N2: 0.833 | O2: 0.252 | P2: 14792 | Q2: 190 | R2: 5 | S2: 422 | T2: 422 | U2: 1 | V2: 2757 | W2: 0 | X2: 23499 | Y2: 0 | Z2: 53088 | AA2: 0.478 | AB2: 1903 | AC2: 0.22430556 | AD2: 9 | AE2: 4138 | AF2: 7 | AG2: 0 | AH2: 6 | AI2: 0
A3: 260507 | B3: 3 | C3: 天辉 | D3: 负 | E3: 12 | F3: ldxy | G3: =VLOOKUP(F3,选手工资!A1:B28,2,FALSE) -> 8 | H3: 灰烬之灵 | I3: 2 | J3: 20 | K3: 6 | L3: 9 | M3: 3 | N3: 0.75 | O3: 0.425 | P3: 10768 | Q3: 155 | R3: 8 | S3: 412 | T3: 663 | U3: 1 | V3: 0 | W3: 0 | X3: 39569 | Y3: 0 | Z3: 67956 | AA3: 0.559 | AB3: 1335 | AC3: 0.25347222 | AD3: 5 | AE3: 3292 | AF3: 8 | AG3: 100 | AH3: 0 | AI3: 1
A4: 260507 | B4: 3 | C4: 天辉 | D4: 负 | E4: 12 | F4: 小孩 | G4: =VLOOKUP(F4,选手工资!A3:B30,2,FALSE) -> 6 | H4: 炼金术士 | I4: 1 | J4: 18 | K4: 2 | L4: 6 | M4: 3 | N4: 0.417 | O4: 0.144 | P4: 11066 | Q4: 185 | R4: 5 | S4: 475 | T4: 543 | U4: 0 | V4: 0 | W4: 0 | X4: 13397 | Y4: 0 | Z4: 28450 | AA4: 0.342 | AB4: 466 | AC4: 0.12638889 | AD4: 12 | AE4: 3203 | AF4: 5 | AG4: 50 | AH4: 5 | AI4: 0
A5: 260507 | B5: 3 | C5: 天辉 | D5: 负 | E5: 12 | F5: 记者 | G5: =VLOOKUP(F5,选手工资!A4:B31,2,FALSE) -> 4.5 | H5: 裂魂人 | I5: 4 | J5: 11 | K5: 0 | L5: 10 | M5: 8 | N5: 0.667 | O5: 0.107 | P5: 5200 | Q5: 41 | R5: 1 | S5: 200 | T5: 215 | U5: 5 | V5: 0 | W5: 0 | X5: 9932 | Y5: 0 | Z5: 29636 | AA5: 0.395 | AB5: 811 | AC5: 0.20277778 | AD5: 1 | AE5: 1838 | AF5: 4 | AG5: 200 | AH5: 1 | AI5: 2
A6: 260507 | B6: 3 | C6: 天辉 | D6: 负 | E6: 12 | F6: 小队 | G6: =VLOOKUP(F6,选手工资!A5:B32,2,FALSE) -> 2 | H6: 杰奇洛 | I6: 5 | J6: 12 | K6: 0 | L6: 13 | M6: 7 | N6: 0.583 | O6: 0.072 | P6: 5275 | Q6: 24 | R6: 1 | S6: 221 | T6: 290 | U6: 0 | V6: 0 | W6: 0 | X6: 6743 | Y6: 0 | Z6: 33480 | AA6: 0.35 | AB6: 729 | AC6: 0.25069444 | AD6: 11 | AE6: 1422 | AF6: 4 | AG6: 550 | AH6: 3 | AI6: 7
A7: 260507 | B7: 3 | C7: 夜魇 | D7: 胜 | E7: 45 | F7: 马忠 | G7: 8 | H7: 破晓辰星 | I7: 3 | J7: 22 | K7: 13 | L7: 2 | M7: 24 | N7: 0.822 | O7: 0.375 | P7: 19908 | Q7: 250 | R7: 17 | S7: 677 | T7: 829 | U7: 2 | V7: 6184 | W7: 0 | X7: 43568 | Y7: 5336 | Z7: 44993 | AA7: 0.466 | AB7: 632 | AC7: 0.032638889 | AD7: 8 | AE7: 5050 | AF7: 7 | AG7: 130 | AH7: 0 | AI7: 0
A8: 260507 | B8: 3 | C8: 夜魇 | D8: 胜 | E8: 45 | F8: xian | G8: 7.5 | H8: 帕克 | I8: 2 | J8: 21 | K8: 13 | L8: 3 | M8: 14 | N8: 0.6 | O8: 0.304 | P8: 18402 | Q8: 231 | R8: 11 | S8: 648 | T8: 741 | U8: 3 | V8: 0 | W8: 0 | X8: 35284 | Y8: 11036 | Z8: 31350 | AA8: 0.397 | AB8: 994 | AC8: 0.075694444 | AD8: 4 | AE8: 4178 | AF8: 8 | AG8: 50 | AH8: 1 | AI8: 4
A9: 260507 | B9: 3 | C9: 夜魇 | D9: 胜 | E9: 45 | F9: 机器人 | G9: =VLOOKUP(F9,选手工资!A9:B36,2,FALSE) -> 5 | H9: 斯拉克 | I9: 1 | J9: 19 | K9: 3 | L9: 4 | M9: 8 | N9: 0.244 | O9: 0.102 | P9: 16855 | Q9: 217 | R9: 23 | S9: 526 | T9: 596 | U9: 0 | V9: 0 | W9: 0 | X9: 11863 | Y9: 7328 | Z9: 33263 | AA9: 0.444 | AB9: 708 | AC9: 0.10138889 | AD9: 10 | AE9: 3843 | AF9: 6 | AG9: 0 | AH9: 1 | AI9: 0
A10: 260507 | B10: 3 | C10: 夜魇 | D10: 胜 | E10: 45 | F10: 教练 | G10: =VLOOKUP(F10,选手工资!A6:B33,2,FALSE) -> 6 | H10: 邪影芳灵 | I10: 4 | J10: 17 | K10: 15 | L10: 0 | M10: 16 | N10: 0.689 | O10: 0.144 | P10: 13060 | Q10: 29 | R10: 8 | S10: 425 | T10: 519 | U10: 2 | V10: 1638 | W10: 0 | X10: 16703 | Y10: 2543 | Z10: 21057 | AA10: 0.332 | AB10: 0 | AC10: 0 | AD10: 7 | AE10: 3313 | AF10: 7 | AG10: 650 | AH10: 2 | AI10: 4
A11: 260507 | B11: 3 | C11: 夜魇 | D11: 胜 | E11: 45 | F11: 呆叔 | G11: =VLOOKUP(F11,选手工资!A8:B35,2,FALSE) -> 4 | H11: 不朽尸王 | I11: 5 | J11: 17 | K11: 1 | L11: 3 | M11: 29 | N11: 0.667 | O11: 0.075 | P11: 10394 | Q11: 41 | R11: 1 | S11: 299 | T11: 489 | U11: 2 | V11: 8798 | W11: 1 | X11: 8674 | Y11: 613 | Z11: 26040 | AA11: 0.321 | AB11: 124 | AC11: 0.021527778 | AD11: 3 | AE11: 1833 | AF11: 5 | AG11: 800 | AH11: 0 | AI11: 5
A14: 比赛ID | B14: 8801445758
A15: 比赛时长 | B15: 32:39

Sheet 260508-1
A1: 日期 | B1: 场次 | C1: 阵营 | D1: 结果 | E1: 队伍击杀 | F1: 选手 | G1: 选手工资 | H1: 英雄 | I1: 位置 | J1: 等级 | K1: K | L1: D | M1: A | N1: 参战率 | O1: 输出占比 | P1: 财产 | Q1: 正补 | R1: 反补 | S1: GPM | T1: XPM | U1: 赏金神符 | V1: 治疗 | W1: 前哨 | X1: 英雄伤害 | Y1: 建筑伤害 | Z1: 承伤减免前 | AA1: 伤害减免比例 | AB1: 死亡损失金钱 | AC1: 死亡时间 | AD1: 挑选顺位 | AE1: 10分钟财产 | AF1: 10分钟等级 | AG1: 辅助道具金钱 | AH1: 堆野数 | AI1: 反眼数
A2: 260508 | B2: 1 | C2: 天辉 | D2: 胜 | E2: 44 | F2: D | G2: 9.5 | H2: 凯 | I2: 2 | J2: 27 | K2: 23 | L2: 2 | M2: 12 | N2: 0.795 | O2: 0.39 | P2: 23509 | Q2: 261 | R2: 20 | S2: 708 | T2: 1250 | U2: 0 | V2: 0 | W2: 1 | X2: 50340 | Y2: 2195 | Z2: 57930 | AA2: 0.547 | AB2: 712 | AC2: 0.027777778 | AD2: 5 | AE2: 4679 | AF2: 9 | AG2: 50 | AH2: 0 | AI2: 2
A3: 260508 | B3: 1 | C3: 天辉 | D3: 胜 | E3: 44 | F3: 小孩 | G3: =VLOOKUP(F3,选手工资!A5:C32,3,FALSE) -> 5.5 | H3: 潮汐猎人 | I3: 3 | J3: 21 | K3: 4 | L3: 6 | M3: 26 | N3: 0.682 | O3: 0.202 | P3: 16553 | Q3: 235 | R3: 7 | S3: 499 | T3: 703 | U3: 2 | V3: 5265 | W3: 0 | X3: 26079 | Y3: 237 | Z3: 60311 | AA3: 0.501 | AB3: 1335 | AC3: 0.17777778 | AD3: 6 | AE3: 4874 | AF3: 7 | AG3: 0 | AH3: 2 | AI3: 0
A4: 260508 | B4: 1 | C4: 天辉 | D4: 胜 | E4: 44 | F4: 郝哥 | G4: =VLOOKUP(F4,选手工资!A3:C30,3,FALSE) -> 7.5 | H4: 露娜 | I4: 1 | J4: 24 | K4: 9 | L4: 5 | M4: 14 | N4: 0.523 | O4: 0.208 | P4: 23666 | Q4: 395 | R4: 10 | S4: 709 | T4: 946 | U4: 5 | V4: 0 | W4: 1 | X4: 26800 | Y4: 7272 | Z4: 31121 | AA4: 0.541 | AB4: 831 | AC4: 0.12986111 | AD4: 9 | AE4: 3685 | AF4: 7 | AG4: 50 | AH4: 2 | AI4: 0
A5: 260508 | B5: 1 | C5: 天辉 | D5: 胜 | E5: 44 | F5: 之后 | G5: =VLOOKUP(F5,选手工资!A2:C29,3,FALSE) -> 1 | H5: 水晶室女 | I5: 5 | J5: 19 | K5: 1 | L5: 7 | M5: 24 | N5: 0.568 | O5: 0.105 | P5: 8787 | Q5: 62 | R5: 1 | S5: 276 | T5: 586 | U5: 0 | V5: 0 | W5: 0 | X5: 13491 | Y5: 43 | Z5: 18428 | AA5: 0.475 | AB5: 495 | AC5: 0.15277778 | AD5: 1 | AE5: 1810 | AF5: 5 | AG5: 530 | AH5: 7 | AI5: 6
A6: 260508 | B6: 1 | C6: 天辉 | D6: 胜 | E6: 44 | F6: 博洋 | G6: =VLOOKUP(F6,选手工资!A6:C33,3,FALSE) -> 6.5 | H6: 裂魂人 | I6: 4 | J6: 18 | K6: 6 | L6: 6 | M6: 29 | N6: 0.795 | O6: 0.096 | P6: 11154 | Q6: 86 | R6: 1 | S6: 364 | T6: 535 | U6: 3 | V6: 564 | W6: 0 | X6: 12339 | Y6: 24 | Z6: 27916 | AA6: 0.408 | AB6: 761 | AC6: 0.14791667 | AD6: 6 | AE6: 2238 | AF6: 4 | AG6: 880 | AH6: 1 | AI6: 8
A7: 260508 | B7: 1 | C7: 夜魇 | D7: 负 | E7: 26 | F7: 记者 | G7: =VLOOKUP(F7,选手工资!A8:C35,3,FALSE) -> 4 | H7: 破晓辰星 | I7: 3 | J7: 19 | K7: 6 | L7: 6 | M7: 9 | N7: 0.577 | O7: 0.21 | P7: 15046 | Q7: 233 | R7: 9 | S7: 474 | T7: 598 | U7: 2 | V7: 3888 | W7: 0 | X7: 20383 | Y7: 633 | Z7: 59047 | AA7: 0.491 | AB7: 1618 | AC7: 0.19236111 | AD7: 8 | AE7: 4138 | AF7: 7 | AG7: 0 | AH7: 0 | AI7: 0
A8: 260508 | B8: 1 | C8: 夜魇 | D8: 负 | E8: 26 | F8: xian | G8: 10.5 | H8: 森海飞霞 | I8: 2 | J8: 21 | K8: 7 | L8: 7 | M8: 8 | N8: 0.577 | O8: 0.236 | P8: 14747 | Q8: 222 | R8: 8 | S8: 498 | T8: 681 | U8: 2 | V8: 0 | W8: 0 | X8: 22871 | Y8: 0 | Z8: 41541 | AA8: 0.451 | AB8: 1448 | AC8: 0.16388889 | AD8: 10 | AE8: 3487 | AF8: 7 | AG8: 50 | AH8: 2 | AI8: 0
A9: 260508 | B9: 1 | C9: 夜魇 | D9: 负 | E9: 26 | F9: 机器人 | G9: =VLOOKUP(F9,选手工资!A10:C37,3,FALSE) -> 5 | H9: 小小 | I9: 1 | J9: 21 | K9: 8 | L9: 8 | M9: 5 | N9: 0.5 | O9: 0.258 | P9: 17237 | Q9: 256 | R9: 4 | S9: 541 | T9: 732 | U9: 1 | V9: 0 | W9: 0 | X9: 24991 | Y9: 449 | Z9: 60584 | AA9: 0.399 | AB9: 1945 | AC9: 0.26458333 | AD9: 3 | AE9: 4013 | AF9: 6 | AG9: 0 | AH9: 0 | AI9: 0
A10: 260508 | B10: 1 | C10: 夜魇 | D10: 负 | E10: 26 | F10: 马忠 | G10: 8.5 | H10: 拉比克 | I10: 4 | J10: 16 | K10: 4 | L10: 10 | M10: 16 | N10: 0.769 | O10: 0.203 | P10: 8479 | Q10: 69 | R10: 1 | S10: 317 | T10: 421 | U10: 1 | V10: 0 | W10: 1 | X10: 19647 | Y10: 0 | Z10: 31837 | AA10: 0.331 | AB10: 1280 | AC10: 0.25277778 | AD10: 4 | AE10: 2289 | AF10: 6 | AG10: 800 | AH10: 3 | AI10: 5
A11: 260508 | B11: 1 | C11: 夜魇 | D11: 负 | E11: 26 | F11: 小队 | G11: =VLOOKUP(F11,选手工资!A7:C34,3,FALSE) -> 2 | H11: 干扰者 | I11: 5 | J11: 15 | K11: 1 | L11: 13 | M11: 16 | N11: 0.654 | O11: 0.092 | P11: 6586 | Q11: 18 | R11: 0 | S11: 250 | T11: 388 | U11: 1 | V11: 0 | W11: 0 | X11: 8955 | Y11: 0 | Z11: 25735 | AA11: 0.281 | AB11: 820 | AC11: 0.26597222 | AD11: 7 | AE11: 1485 | AF11: 5 | AG11: 550 | AH11: 2 | AI11: 4
A13: 比赛ID | B13: 8802574130
A14: 比赛时长 | B14: 35:19

Sheet 260508-2
A1: 日期 | B1: 场次 | C1: 阵营 | D1: 结果 | E1: 队伍击杀 | F1: 选手 | G1: 选手工资 | H1: 英雄 | I1: 位置 | J1: 等级 | K1: K | L1: D | M1: A | N1: 参战率 | O1: 输出占比 | P1: 财产 | Q1: 正补 | R1: 反补 | S1: GPM | T1: XPM | U1: 赏金神符 | V1: 治疗 | W1: 前哨 | X1: 英雄伤害 | Y1: 建筑伤害 | Z1: 承伤减免前 | AA1: 伤害减免比例 | AB1: 死亡损失金钱 | AC1: 死亡时间 | AD1: 挑选顺位 | AE1: 10分钟财产 | AF1: 10分钟等级 | AG1: 辅助道具金钱 | AH1: 堆野数 | AI1: 反眼数
A2: 260508 | B2: 2 | C2: 天辉 | D2: 胜 | E2: 37 | F2: D | G2: =VLOOKUP(F2,选手工资!$A:$C,3,FALSE) -> 9.5 | H2: 石鳞剑士 | I2: 2 | J2: 30 | K2: 11 | L2: 4 | M2: 14 | N2: 0.676 | O2: 0.331 | P2: 40443 | Q2: 754 | R2: 2 | S2: 798 | T2: 1096 | U2: 3 | V2: 0 | W2: 2 | X2: 61393 | Y2: 2419 | Z2: 78986 | AA2: 0.615 | AB2: 1898 | AC2: 0.11041667 | AD2: 9 | AE2: 4392 | AF2: 8 | AG2: 100 | AH2: 0 | AI2: 4
A3: 260508 | B3: 2 | C3: 天辉 | D3: 胜 | E3: 37 | F3: 小孩 | G3: =VLOOKUP(F3,选手工资!$A:$C,3,FALSE) -> 5.5 | H3: 齐天大圣 | I3: 1 | J3: 29 | K3: 11 | L3: 7 | M3: 11 | N3: 0.595 | O3: 0.296 | P3: 41183 | Q3: 681 | R3: 40 | S3: 734 | T3: 1061 | U3: 2 | V3: 0 | W3: 0 | X3: 54927 | Y3: 21087 | Z3: 92383 | AA3: 0.526 | AB3: 3001 | AC3: 0.32291667 | AD3: 6 | AE3: 4340 | AF3: 7 | AG3: 0 | AH3: 1 | AI3: 1
A4: 260508 | B4: 2 | C4: 夜魇 | D4: 负 | E4: 39 | F4: 郝哥 | G4: =VLOOKUP(F4,选手工资!$A:$C,3,FALSE) -> 7.5 | H4: 宙斯 | I4: 2 | J4: 28 | K4: 9 | L4: 5 | M4: 23 | N4: 0.821 | O4: 0.41 | P4: 34118 | Q4: 665 | R4: 7 | S4: 690 | T4: 929 | U4: 3 | V4: 0 | W4: 0 | X4: 67958 | Y4: 49 | Z4: 47727 | AA4: 0.364 | AB4: 1900 | AC4: 0.072222222 | AD4: 10 | AE4: 4301 | AF4: 8 | AG4: 50 | AH4: 3 | AI4: 4
A5: 260508 | B5: 2 | C5: 夜魇 | D5: 负 | E5: 39 | F5: 博洋 | G5: =VLOOKUP(F5,选手工资!$A:$C,3,FALSE) -> 6.5 | H5: 冥魂大帝 | I5: 1 | J5: 29 | K5: 14 | L5: 5 | M5: 10 | N5: 0.615 | O5: 0.278 | P5: 32995 | Q5: 585 | R5: 13 | S5: 700 | T5: 977 | U5: 5 | V5: 0 | W5: 0 | X5: 46135 | Y5: 4681 | Z5: 151944 | AA5: 0.6 | AB5: 3468 | AC5: 0.22291667 | AD5: 8 | AE5: 4196 | AF5: 7 | AG5: 0 | AH5: 0 | AI5: 0
A6: 260508 | B6: 2 | C6: 夜魇 | D6: 负 | E6: 39 | F6: 阵容 | G6: =VLOOKUP(F6,选手工资!$A:$C,3,FALSE) -> 7 | H6: 暗夜魔王 | I6: 3 | J6: 27 | K6: 11 | L6: 6 | M6: 12 | N6: 0.59 | O6: 0.164 | P6: 21745 | Q6: 345 | R6: 10 | S6: 462 | T6: 744 | U6: 3 | V6: 0 | W6: 0 | X6: 27185 | Y6: 665 | Z6: 85550 | AA6: 0.564 | AB6: 1885 | AC6: 0.20486111 | AD6: 7 | AE6: 3937 | AF6: 7 | AG6: 500 | AH6: 0 | AI6: 1
A7: 260508 | B7: 2 | C7: 天辉 | D7: 胜 | E7: 37 | F7: 之后 | G7: =VLOOKUP(F7,选手工资!$A:$C,3,FALSE) -> 1 | H7: 撼地者 | I7: 3 | J7: 25 | K7: 4 | L7: 9 | M7: 14 | N7: 0.486 | O7: 0.125 | P7: 20017 | Q7: 311 | R7: 1 | S7: 412 | T7: 633 | U7: 2 | V7: 0 | W7: 1 | X7: 23196 | Y7: 643 | Z7: 69379 | AA7: 0.431 | AB7: 2464 | AC7: 0.28680556 | AD7: 2 | AE7: 2872 | AF7: 6 | AG7: 0 | AH7: 2 | AI7: 0
A8: 260508 | B8: 2 | C8: 天辉 | D8: 胜 | E8: 37 | F8: 老虎 | G8: =VLOOKUP(F8,选手工资!$A:$C,3,FALSE) -> 5 | H8: 沉默术士 | I8: 5 | J8: 24 | K8: 5 | L8: 9 | M8: 18 | N8: 0.622 | O8: 0.091 | P8: 17706 | Q8: 127 | R8: 0 | S8: 326 | T8: 552 | U8: 4 | V8: 0 | W8: 0 | X8: 16960 | Y8: 393 | Z8: 36850 | AA8: 0.499 | AB8: 1406 | AC8: 0.26111111 | AD8: 1 | AE8: 2812 | AF8: 6 | AG8: 1100 | AH8: 1 | AI8: 6
A9: 260508 | B9: 2 | C9: 夜魇 | D9: 负 | E9: 39 | F9: 教练 | G9: =VLOOKUP(F9,选手工资!$A:$C,3,FALSE) -> 6 | H9: 莉娜 | I9: 5 | J9: 22 | K9: 3 | L9: 12 | M9: 13 | N9: 0.41 | O9: 0.073 | P9: 12964 | Q9: 196 | R9: 1 | S9: 314 | T9: 480 | U9: 2 | V9: 0 | W9: 1 | X9: 12166 | Y9: 373 | Z9: 41144 | AA9: 0.425 | AB9: 1540 | AC9: 0.38333333 | AD9: 3 | AE9: 2490 | AF9: 6 | AG9: 3050 | AH9: 1 | AI9: 8
A10: 260508 | B10: 2 | C10: 天辉 | D10: 胜 | E10: 37 | F10: 马忠 | G10: =VLOOKUP(F10,选手工资!$A:$C,3,FALSE) -> 8.5 | H10: 拉比克 | I10: 4 | J10: 26 | K10: 5 | L10: 10 | M10: 24 | N10: 0.784 | O10: 0.156 | P10: 20599 | Q10: 189 | R10: 4 | S10: 414 | T10: 736 | U10: 6 | V10: 469 | W10: 0 | X10: 28908 | Y10: 192 | Z10: 61157 | AA10: 0.451 | AB10: 1330 | AC10: 0.21597222 | AD10: 5 | AE10: 2452 | AF10: 5 | AG10: 650 | AH10: 4 | AI10: 2
A11: 260508 | B11: 2 | C11: 夜魇 | D11: 负 | E11: 39 | F11: 螃蟹 | G11: =VLOOKUP(F11,选手工资!$A:$C,3,FALSE) -> #N/A | H11: 风行者 | I11: 4 | J11: 26 | K11: 2 | L11: 9 | M11: 21 | N11: 0.59 | O11: 0.074 | P11: 14250 | Q11: 118 | R11: 2 | S11: 332 | T11: 659 | U11: 0 | V11: 3332 | W11: 0 | X11: 12316 | Y11: 3498 | Z11: 57399 | AA11: 0.432 | AB11: 1413 | AC11: 0.23055556 | AD11: 4 | AE11: 1873 | AF11: 5 | AG11: 830 | AH11: 3 | AI11: 3
A13: 比赛ID | B13: 8802642559
A14: 比赛时长 | B14: 58:44

Sheet 260508-3
A1: 日期 | B1: 场次 | C1: 阵营 | D1: 结果 | E1: 队伍击杀 | F1: 选手 | G1: 选手工资 | H1: 英雄 | I1: 位置 | J1: 等级 | K1: K | L1: D | M1: A | N1: 参战率 | O1: 输出占比 | P1: 财产 | Q1: 正补 | R1: 反补 | S1: GPM | T1: XPM | U1: 赏金神符 | V1: 治疗 | W1: 前哨 | X1: 英雄伤害 | Y1: 建筑伤害 | Z1: 承伤减免前 | AA1: 伤害减免比例 | AB1: 死亡损失金钱 | AC1: 死亡时间 | AD1: 挑选顺位 | AE1: 10分钟财产 | AF1: 10分钟等级 | AG1: 辅助道具金钱 | AH1: 堆野数 | AI1: 反眼数
A2: 260508 | B2: 3 | C2: 天辉 | D2: 负 | E2: 47 | F2: ldxy | G2: =VLOOKUP(F2,选手工资!$A:$C,3,FALSE) -> 7.5 | H2: 昆卡 | I2: 2 | J2: 28 | K2: 8 | L2: 10 | M2: 18 | N2: 0.553 | O2: 0.216 | P2: 29961 | Q2: 510 | R2: 4 | S2: 613 | T2: 966 | U2: 5 | V2: 0 | W2: 0 | X2: 40079 | Y2: 633 | Z2: 107193 | AA2: 0.516 | AB2: 2372 | AC2: 0.32291667 | AD2: 6 | AE2: 3121 | AF2: 8 | AG2: 130 | AH2: 0 | AI2: 1
A3: 260508 | B3: 3 | C3: 天辉 | D3: 负 | E3: 47 | F3: 马忠 | G3: =VLOOKUP(F3,选手工资!$A:$C,3,FALSE) -> 8.5 | H3: 小小 | I3: 1 | J3: 29 | K3: 12 | L3: 9 | M3: 21 | N3: 0.702 | O3: 0.317 | P3: 35120 | Q3: 616 | R3: 17 | S3: 718 | T3: 1070 | U3: 0 | V3: 0 | W3: 0 | X3: 58970 | Y3: 3317 | Z3: 106107 | AA3: 0.438 | AB3: 2371 | AC3: 0.30763889 | AD3: 2 | AE3: 4384 | AF3: 7 | AG3: 80 | AH3: 1 | AI3: 4
A4: 260508 | B4: 3 | C4: 天辉 | D4: 负 | E4: 47 | F4: 阵容 | G4: =VLOOKUP(F4,选手工资!$A:$C,3,FALSE) -> 7 | H4: 斯拉达 | I4: 3 | J4: 27 | K4: 14 | L4: 11 | M4: 18 | N4: 0.681 | O4: 0.16 | P4: 25905 | Q4: 364 | R4: 5 | S4: 555 | T4: 812 | U4: 7 | V4: 0 | W4: 1 | X4: 29692 | Y4: 333 | Z4: 99393 | AA4: 0.544 | AB4: 2862 | AC4: 0.40555556 | AD4: 9 | AE4: 4542 | AF4: 6 | AG4: 260 | AH4: 0 | AI4: 0
A5: 260508 | B5: 3 | C5: 天辉 | D5: 负 | E5: 47 | F5: 呆叔 | G5: =VLOOKUP(F5,选手工资!$A:$C,3,FALSE) -> 4 | H5: 干扰者 | I5: 5 | J5: 25 | K5: 7 | L5: 10 | M5: 29 | N5: 0.766 | O5: 0.109 | P5: 14899 | Q5: 112 | R5: 1 | S5: 357 | T5: 609 | U5: 5 | V5: 1047 | W5: 1 | X5: 20208 | Y5: 143 | Z5: 52550 | AA5: 0.431 | AB5: 1740 | AC5: 0.25763889 | AD5: 1 | AE5: 1742 | AF5: 5 | AG5: 2100 | AH5: 4 | AI5: 4
A6: 260508 | B6: 3 | C6: 天辉 | D6: 负 | E6: 47 | F6: 记者 | G6: =VLOOKUP(F6,选手工资!$A:$C,3,FALSE) -> 4 | H6: 工程师 | I6: 4 | J6: 25 | K6: 6 | L6: 16 | M6: 24 | N6: 0.638 | O6: 0.199 | P6: 18569 | Q6: 173 | R6: 1 | S6: 388 | T6: 648 | U6: 0 | V6: 6220 | W6: 0 | X6: 36927 | Y6: 994 | Z6: 69448 | AA6: 0.505 | AB6: 2782 | AC6: 0.46319444 | AD6: 5 | AE6: 1485 | AF6: 4 | AG6: 660 | AH6: 4 | AI6: 4
A7: 260508 | B7: 3 | C7: 夜魇 | D7: 胜 | E7: 56 | F7: 小孩 | G7: =VLOOKUP(F7,选手工资!$A:$C,3,FALSE) -> 5.5 | H7: 冥界亚龙 | I7: 2 | J7: 28 | K7: 21 | L7: 7 | M7: 17 | N7: 0.679 | O7: 0.285 | P7: 29579 | Q7: 229 | R7: 13 | S7: 546 | T7: 898 | U7: 2 | V7: 216 | W7: 2 | X7: 63123 | Y7: 10725 | Z7: 69705 | AA7: 0.543 | AB7: 2735 | AC7: 0.34722222 | AD7: 10 | AE7: 3884 | AF7: 8 | AG7: 200 | AH7: 0 | AI7: 8
A8: 260508 | B8: 3 | C8: 夜魇 | D8: 胜 | E8: 56 | F8: 博洋 | G8: =VLOOKUP(F8,选手工资!$A:$C,3,FALSE) -> 6.5 | H8: 炼金术士 | I8: 1 | J8: 30 | K8: 13 | L8: 6 | M8: 28 | N8: 0.732 | O8: 0.301 | P8: 29092 | Q8: 550 | R8: 8 | S8: 863 | T8: 1249 | U8: 5 | V8: 0 | W8: 0 | X8: 66461 | Y8: 13930 | Z8: 86831 | AA8: 0.472 | AB8: 1315 | AC8: 0.16944444 | AD8: 3 | AE8: 4653 | AF8: 6 | AG8: 900 | AH8: 7 | AI8: 1
A9: 260508 | B9: 3 | C9: 夜魇 | D9: 胜 | E9: 56 | F9: 机器人 | G9: =VLOOKUP(F9,选手工资!$A:$C,3,FALSE) -> 5 | H9: 暗夜魔王 | I9: 3 | J9: 26 | K9: 9 | L9: 13 | M9: 22 | N9: 0.554 | O9: 0.157 | P9: 30344 | Q9: 315 | R9: 11 | S9: 514 | T9: 741 | U9: 4 | V9: 0 | W9: 0 | X9: 34714 | Y9: 3061 | Z9: 103314 | AA9: 0.5 | AB9: 3917 | AC9: 0.52708333 | AD9: 8 | AE9: 3396 | AF9: 6 | AG9: 160 | AH9: 1 | AI9: 0
A10: 260508 | B10: 3 | C10: 夜魇 | D10: 胜 | E10: 56 | F10: 郝哥 | G10: =VLOOKUP(F10,选手工资!$A:$C,3,FALSE) -> 7.5 | H10: 司夜刺客 | I10: 4 | J10: 23 | K10: 7 | L10: 12 | M10: 29 | N10: 0.643 | O10: 0.143 | P10: 22418 | Q10: 109 | R10: 0 | S10: 399 | T10: 505 | U10: 2 | V10: 0 | W10: 0 | X10: 31589 | Y10: 1873 | Z10: 72232 | AA10: 0.491 | AB10: 3242 | AC10: 0.48402778 | AD10: 7 | AE10: 2356 | AF10: 5 | AG10: 1140 | AH10: 0 | AI10: 6
A11: 260508 | B11: 3 | C11: 夜魇 | D11: 胜 | E11: 56 | F11: valar | G11: =VLOOKUP(F11,选手工资!$A:$C,3,FALSE) -> 6 | H11: 天涯墨客 | I11: 5 | J11: 23 | K11: 6 | L11: 9 | M11: 29 | N11: 0.625 | O11: 0.114 | P11: 17918 | Q11: 68 | R11: 1 | S11: 330 | T11: 540 | U11: 1 | V11: 0 | W11: 1 | X11: 25230 | Y11: 405 | Z11: 31281 | AA11: 0.366 | AB11: 1522 | AC11: 0.28541667 | AD11: 4 | AE11: 2236 | AF11: 6 | AG11: 1400 | AH11: 4 | AI11: 7
A13: 比赛ID | B13: 8802748606
A14: 比赛时长 | B14: 56:51

Sheet 260509-1
A1: 日期 | B1: 场次 | C1: 阵营 | D1: 结果 | E1: 队伍击杀 | F1: 选手 | G1: 选手工资 | H1: 英雄 | I1: 位置 | J1: 等级 | K1: K | L1: D | M1: A | N1: 参战率 | O1: 输出占比 | P1: 财产 | Q1: 正补 | R1: 反补 | S1: GPM | T1: XPM | U1: 赏金神符 | V1: 治疗 | W1: 前哨 | X1: 英雄伤害 | Y1: 建筑伤害 | Z1: 承伤减免前 | AA1: 伤害减免比例 | AB1: 死亡损失金钱 | AC1: 死亡时间 | AD1: 挑选顺位 | AE1: 10分钟财产 | AF1: 10分钟等级 | AG1: 辅助道具金钱 | AH1: 堆野数 | AI1: 反眼数
A2: 260509 | B2: 1 | C2: 天辉 | D2: 胜 | E2: 43 | F2: 阵容 | G2: =VLOOKUP(F2,选手工资!$A:$D,4,FALSE) -> 6 | H2: 冥界亚龙 | I2: 2 | J2: 27 | K2: 12 | L2: 5 | M2: 25 | N2: 0.86 | O2: 0.332 | P2: 29439 | Q2: 340 | R2: 20 | S2: 625 | T2: 979 | U2: 4 | V2: 177 | W2: 0 | X2: 55392 | Y2: 2651 | Z2: 96192 | AA2: 0.639 | AB2: 1251 | AC2: 0.18541667 | AD2: 9 | AE2: 3946 | AF2: 8 | AG2: 100 | AH2: 0 | AI2: 2
A3: 260509 | B3: 1 | C3: 天辉 | D3: 胜 | E3: 43 | F3: 郝哥 | G3: =VLOOKUP(F3,选手工资!$A:$D,4,FALSE) -> 8.5 | H3: 虚空假面 | I3: 1 | J3: 28 | K3: 8 | L3: 6 | M3: 30 | N3: 0.884 | O3: 0.26 | P3: 37098 | Q3: 554 | R3: 8 | S3: 755 | T3: 1064 | U3: 4 | V3: 0 | W3: 0 | X3: 43391 | Y3: 16700 | Z3: 101709 | AA3: 0.605 | AB3: 649 | AC3: 0.14097222 | AD3: 5 | AE3: 3838 | AF3: 7 | AG3: 0 | AH3: 1 | AI3: 3
A4: 260509 | B4: 1 | C4: 天辉 | D4: 胜 | E4: 43 | F4: 记者 | G4: =VLOOKUP(F4,选手工资!$A:$D,4,FALSE) -> 3 | H4: 全能骑士 | I4: 3 | J4: 25 | K4: 4 | L4: 8 | M4: 20 | N4: 0.558 | O4: 0.12 | P4: 19642 | Q4: 205 | R4: 5 | S4: 431 | T4: 694 | U4: 1 | V4: 4618 | W4: 0 | X4: 19933 | Y4: 2219 | Z4: 103491 | AA4: 0.658 | AB4: 1981 | AC4: 0.30277778 | AD4: 1 | AE4: 3038 | AF4: 5 | AG4: 50 | AH4: 1 | AI4: 0
A5: 260509 | B5: 1 | C5: 天辉 | D5: 胜 | E5: 43 | F5: 教练 | G5: =VLOOKUP(F5,选手工资!$A:$D,4,FALSE) -> 5 | H5: 森海飞霞 | I5: 4 | J5: 24 | K5: 5 | L5: 7 | M5: 27 | N5: 0.744 | O5: 0.139 | P5: 17355 | Q5: 81 | R5: 0 | S5: 395 | T5: 652 | U5: 2 | V5: 1593 | W5: 3 | X5: 23159 | Y5: 864 | Z5: 43875 | AA5: 0.588 | AB5: 412 | AC5: 0.13611111 | AD5: 6 | AE5: 1930 | AF5: 5 | AG5: 1300 | AH5: 1 | AI5: 11
A6: 260509 | B6: 1 | C6: 天辉 | D6: 胜 | E6: 43 | F6: 小队 | G6: =VLOOKUP(F6,选手工资!$A:$D,4,FALSE) -> 1.5 | H6: 电炎绝手 | I6: 5 | J6: 24 | K6: 13 | L6: 6 | M6: 23 | N6: 0.837 | O6: 0.149 | P6: 19340 | Q6: 61 | R6: 1 | S6: 411 | T6: 637 | U6: 1 | V6: 6211 | W6: 3 | X6: 24866 | Y6: 2240 | Z6: 44936 | AA6: 0.498 | AB6: 741 | AC6: 0.14722222 | AD6: 2 | AE6: 1771 | AF6: 5 | AG6: 500 | AH6: 2 | AI6: 6
A7: 260509 | B7: 1 | C7: 夜魇 | D7: 负 | E7: 32 | F7: 老板 | G7: =VLOOKUP(F7,选手工资!$A:$D,4,FALSE) -> 4.5 | H7: 瘟疫法师 | I7: 2 | J7: 25 | K7: 5 | L7: 5 | M7: 12 | N7: 0.531 | O7: 0.226 | P7: 22140 | Q7: 338 | R7: 2 | S7: 495 | T7: 709 | U7: 4 | V7: 10403 | W7: 0 | X7: 34282 | Y7: 609 | Z7: 66986 | AA7: 0.411 | AB7: 1799 | AC7: 0.19027778 | AD7: 3 | AE7: 3327 | AF7: 7 | AG7: 0 | AH7: 3 | AI7: 0
A8: 260509 | B8: 1 | C8: 夜魇 | D8: 负 | E8: 32 | F8: jin | G8: =VLOOKUP(F8,选手工资!$A:$D,4,FALSE) -> 6 | H8: 莱恩 | I8: 4 | J8: 19 | K8: 3 | L8: 10 | M8: 20 | N8: 0.719 | O8: 0.085 | P8: 11708 | Q8: 64 | R8: 5 | S8: 313 | T8: 394 | U8: 4 | V8: 125 | W8: 0 | X8: 12903 | Y8: 222 | Z8: 41969 | AA8: 0.45 | AB8: 1178 | AC8: 0.31388889 | AD8: 7 | AE8: 2581 | AF8: 6 | AG8: 1600 | AH8: 2 | AI8: 11
A9: 260509 | B9: 1 | C9: 夜魇 | D9: 负 | E9: 32 | F9: 机器猫 | G9: =VLOOKUP(F9,选手工资!$A:$D,4,FALSE) -> 4 | H9: 斧王 | I9: 3 | J9: 22 | K9: 7 | L9: 9 | M9: 12 | N9: 0.594 | O9: 0.194 | P9: 19473 | Q9: 273 | R9: 4 | S9: 439 | T9: 561 | U9: 2 | V9: 0 | W9: 0 | X9: 29399 | Y9: 834 | Z9: 78429 | AA9: 0.495 | AB9: 2188 | AC9: 0.36111111 | AD9: 8 | AE9: 4713 | AF9: 7 | AG9: 50 | AH9: 0 | AI9: 1
A10: 260509 | B10: 1 | C10: 夜魇 | D10: 负 | E10: 32 | F10: 小孩 | G10: =VLOOKUP(F10,选手工资!$A:$D,4,FALSE) -> 7 | H10: 齐天大圣 | I10: 1 | J10: 27 | K10: 14 | L10: 6 | M10: 9 | N10: 0.719 | O10: 0.409 | P10: 28087 | Q10: 488 | R10: 18 | S10: 682 | T10: 876 | U10: 5 | V10: 0 | W10: 4 | X10: 62065 | Y10: 11533 | Z10: 88273 | AA10: 0.519 | AB10: 2831 | AC10: 0.25694444 | AD10: 10 | AE10: 4495 | AF10: 6 | AG10: 0 | AH10: 0 | AI10: 2
A11: 260509 | B11: 1 | C11: 夜魇 | D11: 负 | E11: 32 | F11: 胖蟹 | G11: =VLOOKUP(F11,选手工资!$A:$D,4,FALSE) -> 2.5 | H11: 暗影萨满 | I11: 5 | J11: 18 | K11: 3 | L11: 13 | M11: 19 | N11: 0.688 | O11: 0.087 | P11: 9698 | Q11: 64 | R11: 3 | S11: 278 | T11: 380 | U11: 0 | V11: 0 | W11: 1 | X11: 13162 | Y11: 3968 | Z11: 41355 | AA11: 0.465 | AB11: 1336 | AC11: 0.40833333 | AD11: 4 | AE11: 1557 | AF11: 5 | AG11: 850 | AH11: 0 | AI11: 5
A14: 比赛ID | B14: 8804007353
A15: 比赛时长 | B15: 50:13

Sheet 260509-2
A1: 日期 | B1: 场次 | C1: 阵营 | D1: 结果 | E1: 队伍击杀 | F1: 选手 | G1: 选手工资 | H1: 英雄 | I1: 位置 | J1: 等级 | K1: K | L1: D | M1: A | N1: 参战率 | O1: 输出占比 | P1: 财产 | Q1: 正补 | R1: 反补 | S1: GPM | T1: XPM | U1: 赏金神符 | V1: 治疗 | W1: 前哨 | X1: 英雄伤害 | Y1: 建筑伤害 | Z1: 承伤减免前 | AA1: 伤害减免比例 | AB1: 死亡损失金钱 | AC1: 死亡时间 | AD1: 挑选顺位 | AE1: 10分钟财产 | AF1: 10分钟等级 | AG1: 辅助道具金钱 | AH1: 堆野数 | AI1: 反眼数
A2: 260509 | B2: 2 | C2: 天辉 | D2: 负 | E2: 25 | F2: cac | G2: =VLOOKUP(F2,选手工资!$A:$D,4,FALSE) -> 7.5 | H2: 艾欧 | I2: 2 | J2: 24 | K2: 3 | L2: 13 | M2: 17 | N2: 0.8 | O2: 0.262 | P2: 19769 | Q2: 322 | R2: 9 | S2: 474 | T2: 712 | U2: 0 | V2: 5756 | W2: 0 | X2: 32027 | Y2: 591 | Z2: 106404 | AA2: 0.523 | AB2: 2885 | AC2: 0.47638889 | AD2: 9 | AE2: 4109 | AF2: 8 | AG2: 100 | AH2: 2 | AI2: 2
A3: 260509 | B3: 2 | C3: 天辉 | D3: 负 | E3: 25 | F3: 记者 | G3: =VLOOKUP(F3,选手工资!$A:$D,4,FALSE) -> 3 | H3: 全能骑士 | I3: 3 | J3: 22 | K3: 3 | L3: 7 | M3: 4 | N3: 0.28 | O3: 0.171 | P3: 17908 | Q3: 319 | R3: 12 | S3: 425 | T3: 588 | U3: 1 | V3: 2127 | W3: 1 | X3: 20909 | Y3: 434 | Z3: 63778 | AA3: 0.471 | AB3: 2331 | AC3: 0.29444444 | AD3: 6 | AE3: 3773 | AF3: 6 | AG3: 0 | AH3: 1 | AI3: 1
A4: 260509 | B4: 2 | C4: 天辉 | D4: 负 | E4: 25 | F4: 老板 | G4: =VLOOKUP(F4,选手工资!$A:$D,4,FALSE) -> 4.5 | H4: 琼英碧灵 | I4: 1 | J4: 24 | K4: 9 | L4: 11 | M4: 8 | N4: 0.68 | O4: 0.265 | P4: 21996 | Q4: 400 | R4: 11 | S4: 560 | T4: 719 | U4: 3 | V4: 0 | W4: 0 | X4: 32406 | Y4: 718 | Z4: 48122 | AA4: 0.474 | AB4: 2153 | AC4: 0.39097222 | AD4: 2 | AE4: 3697 | AF4: 6 | AG4: 0 | AH4: 4 | AI4: 0
A5: 260509 | B5: 2 | C5: 天辉 | D5: 负 | E5: 25 | F5: 教练 | G5: =VLOOKUP(F5,选手工资!$A:$D,4,FALSE) -> 5 | H5: 克林克兹 | I5: 4 | J5: 24 | K5: 8 | L5: 11 | M5: 9 | N5: 0.68 | O5: 0.194 | P5: 13938 | Q5: 141 | R5: 14 | S5: 382 | T5: 667 | U5: 3 | V5: 0 | W5: 0 | X5: 23700 | Y5: 1553 | Z5: 42098 | AA5: 0.391 | AB5: 1892 | AC5: 0.37638889 | AD5: 5 | AE5: 2524 | AF5: 5 | AG5: 250 | AH5: 2 | AI5: 5
A6: 260509 | B6: 2 | C6: 天辉 | D6: 负 | E6: 25 | F6: ldxy | G6: =VLOOKUP(F6,选手工资!$A:$D,4,FALSE) -> 6.5 | H6: 远古冰魄 | I6: 5 | J6: 23 | K6: 2 | L6: 9 | M6: 20 | N6: 0.88 | O6: 0.109 | P6: 12574 | Q6: 122 | R6: 2 | S6: 343 | T6: 640 | U6: 3 | V6: 393 | W6: 1 | X6: 13276 | Y6: 0 | Z6: 32935 | AA6: 0.509 | AB6: 1272 | AC6: 0.22083333 | AD6: 1 | AE6: 2343 | AF6: 5 | AG6: 1400 | AH6: 4 | AI6: 16
A7: 260509 | B7: 2 | C7: 夜魇 | D7: 胜 | E7: 50 | F7: 郝哥 | G7: =VLOOKUP(F7,选手工资!$A:$D,4,FALSE) -> 8.5 | H7: 痛苦女王 | I7: 2 | J7: 29 | K7: 13 | L7: 2 | M7: 23 | N7: 0.72 | O7: 0.358 | P7: 36609 | Q7: 516 | R7: 15 | S7: 818 | T7: 1197 | U7: 3 | V7: 0 | W7: 0 | X7: 54262 | Y7: 5325 | Z7: 54992 | AA7: 0.521 | AB7: 676 | AC7: 0.084722222 | AD7: 10 | AE7: 4818 | AF7: 9 | AG7: 50 | AH7: 1 | AI7: 1
A8: 260509 | B8: 2 | C8: 夜魇 | D8: 胜 | E8: 50 | F8: 机器猫 | G8: =VLOOKUP(F8,选手工资!$A:$D,4,FALSE) -> 4 | H8: 巨牙海民 | I8: 3 | J8: 26 | K8: 10 | L8: 9 | M8: 20 | N8: 0.6 | O8: 0.211 | P8: 19776 | Q8: 294 | R8: 2 | S8: 542 | T8: 851 | U8: 5 | V8: 0 | W8: 0 | X8: 31944 | Y8: 3167 | Z8: 58730 | AA8: 0.419 | AB8: 2530 | AC8: 0.30555556 | AD8: 7 | AE8: 3771 | AF8: 7 | AG8: 130 | AH8: 0 | AI8: 0
A9: 260509 | B9: 2 | C9: 夜魇 | D9: 胜 | E9: 50 | F9: 小孩 | G9: =VLOOKUP(F9,选手工资!$A:$D,4,FALSE) -> 7 | H9: 虚空假面 | I9: 1 | J9: 28 | K9: 14 | L9: 3 | M9: 19 | N9: 0.66 | O9: 0.221 | P9: 33574 | Q9: 431 | R9: 11 | S9: 746 | T9: 1098 | U9: 4 | V9: 0 | W9: 1 | X9: 33476 | Y9: 10200 | Z9: 53316 | AA9: 0.435 | AB9: 1334 | AC9: 0.14097222 | AD9: 8 | AE9: 3480 | AF9: 6 | AG9: 200 | AH9: 1 | AI9: 6
A10: 260509 | B10: 2 | C10: 夜魇 | D10: 胜 | E10: 50 | F10: 老虎 | G10: =VLOOKUP(F10,选手工资!$A:$D,4,FALSE) -> 5.5 | H10: 森海飞霞 | I10: 4 | J10: 26 | K10: 10 | L10: 8 | M10: 30 | N10: 0.8 | O10: 0.124 | P10: 20560 | Q10: 176 | R10: 0 | S10: 469 | T10: 895 | U10: 3 | V10: 0 | W10: 3 | X10: 18815 | Y10: 4384 | Z10: 26596 | AA10: 0.441 | AB10: 1317 | AC10: 0.24791667 | AD10: 3 | AE10: 2560 | AF10: 5 | AG10: 480 | AH10: 0 | AI10: 5
